Workbook

Sheet 罐底分布测量原始数据
A2: [17:16:30.013]收← | B2: 02 03 22 46 B7 E6 00 C4 C7 20 00 41 30 00 00 C4 C4 00 00 00 00 00 00 00 00 | C2: =MID(B2,1,9) -> 02 03 22
A3: [17:16:30.123]收← | B3: 10 00 00 00 00 00 00 00 00 00 00 00 B4 7A | C3: =MID(B3,1,9) -> 10 00 00
A4: [17:16:30.239]收← | B4: 01 03 00 00 00 10 44 06 | C4: =MID(B4,1,9) -> 01 03 00
A5: [17:16:30.395]收← | B5: 01 03 20 26 67 00 00 C1 FA 00 00 11 23 00 00 00 00 08 40 48 8E 52 20 00 00 F9 CD 00 00 5B 94 00 00 00 00 AA A1 | C5: =MID(B5,1,9) -> 01 03 20
A6: [17:16:31.955]收← | B6: 04 03 00 C8 00 11 04 6D | C6: =MID(B6,1,9) -> 04 03 00
A7: [17:16:32.361]收← | B7: 04 03 22 46 B8 00 00 3F 80 00 00 3F 80 00 00 3F 80 00 00 00 00 00 00 00 00 10 06 00 00 00 00 00 00 00 00 00 00 31 51 | C7: =MID(B7,1,9) -> 04 03 22
A8: [17:16:32.521]收← | B8: 03 03 00 1E 00 05 E4 2D | C8: =MID(B8,1,9) -> 03 03 00
A9: [17:16:32.605]收← | B9: 03 03 0A 31 37 30 39 31 38 30 38 32 31 55 75 | C9: =MID(B9,1,9) -> 03 03 0A
A10: [17:16:32.759]收← | B10: 02 03 00 C8 00 11 04 0B | C10: =MID(B10,1,9) -> 02 03 00
A11: [17:16:32.978]收← | B11: 02 03 22 46 B7 E6 00 C4 C7 20 00 41 30 00 | C11: =MID(B11,1,9) -> 02 03 22
A12: [17:16:33.043]收← | B12: 00 C4 C4 00 00 00 00 00 00 00 00 10 00 | C12: =MID(B12,1,9) -> 00 C4 C4
A13: [17:16:33.104]收← | B13: 00 00 00 00 00 00 00 00 00 00 B4 7A | C13: =MID(B13,1,9) -> 00 00 00
... A2095: [17:25:43.841]收← | B2095: 02 03 00 C8 00 11 04 0B | C2095: =MID(B2095,1,9) -> 02 03 00
A2096: [17:25:43.999]收← | B2096: 2 | C2096: =MID(B2096,1,9) -> 2
A2097: [17:25:44.067]收← | B2097: 03 22 46 B7 E8 00 C4 C7 00 00 41 30 00 | C2097: =MID(B2097,1,9) -> 03 22 46
A2098: [17:25:44.133]收← | B2098: 00 C4 C4 80 00 00 00 00 00 00 00 10 00 | C2098: =MID(B2098,1,9) -> 00 C4 C4
A2099: [17:25:44.190]收← | B2099: 00 00 00 00 00 00 00 00 00 00 F3 AC | C2099: =MID(B2099,1,9) -> 00 00 00
A2100: [17:25:44.298]收← | B2100: 01 03 00 00 00 10 44 06 | C2100: =MID(B2100,1,9) -> 01 03 00
A2101: [17:25:44.489]收← | B2101: 01 03 20 1D 29 00 00 C1 FE 00 00 11 22 00 00 00 00 0C 60 48 8E 52 40 00 00 F9 CD 00 00 5B 94 00 00 00 00 BF 1A | C2101: =MID(B2101,1,9) -> 01 03 20
A2102: [17:25:46.074]收← | B2102: 04 03 00 C8 00 11 04 6D | C2102: =MID(B2102,1,9) -> 04 03 00
A2103: [17:25:46.462]收← | B2103: 04 03 22 46 B8 00 00 3F 80 00 00 3F 80 00 00 3F 80 00 00 00 00 00 00 00 00 10 06 00 00 00 00 00 00 00 00 00 00 31 51 | C2103: =MID(B2103,1,9) -> 04 03 22
A2104: [17:25:46.601]收← | B2104: 03 03 00 1E 00 05 E4 2D | C2104: =MID(B2104,1,9) -> 03 03 00
A2105: [17:25:46.680]收← | B2105: 03 03 0A 31 37 30 39 31 38 30 38 32 31 55 75 | C2105: =MID(B2105,1,9) -> 03 03 0A
A2106: [17:25:46.893]收← | B2106: 02 03 00 C8 00 11 04 0B | C2106: =MID(B2106,1,9) -> 02 03 00
A2107: [17:25:47.143]收← | B2107: 02 03 22 46 B7 E8 00 C4 C7 00 00 41 30 | C2107: =MID(B2107,1,9) -> 02 03 22
A2108: [17:25:47.194]收← | B2108: 00 00 C4 C4 80 00 00 00 00 00 00 00 | C2108: =MID(B2108,1,9) -> 00 00 C4
... A2304: [17:26:36.546]收← | B2304: 02 03 01 75 00 21 95 C7 | C2304: =MID(B2304,1,9) -> 02 03 01
A2305: [17:26:36.692]收← | B2305: 2 | C2305: =MID(B2305,1,9) -> 2
A2306: [17:26:36.756]收← | B2306: 03 42 FF FF 3F 80 00 00 3F 80 00 00 | C2306: =MID(B2306,1,9) -> 03 42 FF
A2307: [17:26:36.899]收← | B2307: 3F 80 00 00 3F 80 00 00 3F 80 00 00 3F 80 00 00 3F 80 00 00 3F 80 00 00 3F 80 00 00 3F 80 00 00 3F 80 00 00 3F 80 00 00 3F | C2307: =MID(B2307,1,9) -> 3F 80 00
A2308: [17:26:37.009]收← | B2308: 80 00 00 3F 80 00 00 3F 80 00 00 3F 80 00 00 1D E6 | C2308: =MID(B2308,1,9) -> 80 00 00
A2309: [17:26:37.153]收← | B2309: 02 03 01 9A 00 21 A4 32 | C2309: =MID(B2309,1,9) -> 02 03 01
A2310: [17:26:37.392]收← | B2310: 02 03 42 FF FF 3F 80 00 00 3F 80 00 00 | C2310: =MID(B2310,1,9) -> 02 03 42
A2311: [17:26:37.507]收← | B2311: 3F 80 00 00 3F 80 00 00 3F 80 00 00 3F 80 00 00 3F 80 00 00 3F 80 00 00 3F | C2311: =MID(B2311,1,9) -> 3F 80 00
A2312: [17:26:37.663]收← | B2312: 80 00 00 3F 80 00 00 3F 80 00 00 3F 80 00 00 3F 80 00 00 3F 80 00 00 3F 80 00 00 3F 80 00 00 1D E6 | C2312: =MID(B2312,1,9) -> 80 00 00
A2313: [17:26:37.771]收← | B2313: 01 03 00 00 00 10 44 06 | C2313: =MID(B2313,1,9) -> 01 03 00
A2314: [17:26:37.946]收← | B2314: 01 03 20 24 4F 00 00 C1 FC 00 00 11 22 00 00 00 00 0C 60 48 8E 51 80 00 00 F9 CD 00 00 5B 94 00 00 00 00 3C A4 | C2314: =MID(B2314,1,9) -> 01 03 20
A2315: [17:26:38.090]收← | B2315: 04 03 00 C8 00 11 04 6D | C2315: =MID(B2315,1,9) -> 04 03 00
A2316: [17:26:38.519]收← | B2316: 04 03 22 46 B8 00 00 3F 80 00 00 3F 80 00 00 3F 80 00 00 00 00 00 00 00 00 10 06 00 00 00 00 00 00 00 00 00 00 31 51 | C2316: =MID(B2316,1,9) -> 04 03 22
A2317: [17:26:38.665]收← | B2317: 03 03 00 1E 00 05 E4 2D | C2317: =MID(B2317,1,9) -> 03 03 00
...

Sheet 分布测量
C1: 0 | D1: 1 | E1: 2 | F1: 3 | G1: 4 | H1: 5 | I1: 6 | J1: 7 | K1: 8 | L1: 9 | M1: 10 | N1: 11 | O1: 12 | P1: 13 | Q1: 14 | R1: 15
C2: 浮子位置 | D2: 浮子状态 | E2: 温度 | F2: 温度状态 | G2: 密度值 | H2: 密度状态 | I2: 下发指令 | J2: 设备工作状态 | K2: （幅值）未知 | L2: 频率值 | M2: 未知状态位 | N2: 温度 | O2: 温度状态 | P2: 液位值 | Q2: 液位状态 | R2: 位置 | S2: 状态解析
A3: [17:16:30.395]收← | B3: 01 03 20 26 67 00 00 C1 FA 00 00 11 23 00 00 00 00 08 40 48 8E 52 20 00 00 F9 CD 00 00 5B 94 00 00 00 00 AA A1 | C3: =HEX2DEC(MID($B3,10+6*C1,2)&MID($B3,13+6*C1,2)) -> 9831 | D3: =HEX2DEC(MID($B3,10+6*D$1,2)&MID($B3,13+6*D$1,2)) -> 0 | E3: =(HEX2DEC(MID($B3,10+6*E$1,2)&MID($B3,13+6*E$1,2))-65536)/100 -> -158.78 | F3: =HEX2DEC(MID($B3,10+6*F$1,2)&MID($B3,13+6*F$1,2)) -> 0 | G3: =HEX2DEC(MID($B3,10+6*G$1,2)&MID($B3,13+6*G$1,2))/10 -> 438.7 | H3: =HEX2DEC(MID($B3,10+6*H$1,2)&MID($B3,13+6*H$1,2)) -> 0 | I3: =HEX2DEC(MID($B3,10+6*I$1,2)&MID($B3,13+6*I$1,2)) -> 0 | J3: =HEX2DEC(MID($B3,10+6*J$1,2)&MID($B3,13+6*J$1,2)) -> 2112 | K3: =HEX2DEC(MID($B3,10+6*K$1,2)&MID($B3,13+6*K$1,2)) -> 18574 | L3: =HEX2DEC(MID($B3,10+6*L$1,2)&MID($B3,13+6*L$1,2))/10 -> 2102.4 | M3: =HEX2DEC(MID($B3,10+6*M$1,2)&MID($B3,13+6*M$1,2)) -> 0 | N3: =(HEX2DEC(MID($B3,10+6*N$1,2)&MID($B3,13+6*N$1,2))-65536)/10 -> -158.7 | O3: =HEX2DEC(MID($B3,10+6*O$1,2)&MID($B3,13+6*O$1,2)) -> 0 | P3: =HEX2DEC(MID($B3,10+6*P$1,2)&MID($B3,13+6*P$1,2)) -> 23444 | Q3: =HEX2DEC(MID($B3,10+6*Q$1,2)&MID($B3,13+6*Q$1,2)) -> 0 | R3: =HEX2DEC(MID($B3,10+6*R$1,2)&MID($B3,13+6*R$1,2)) -> 0 | S3: =VLOOKUP(J3,设备状态表!$D$3:$E$14,2,0) -> 向下运动到固定点监测
A4: [17:16:33.404]收← | B4: 01 03 20 26 00 00 00 C1 FA 00 00 11 22 00 00 00 00 08 40 48 8E 52 40 00 00 F9 CD 00 00 5B 94 00 00 00 00 17 68 | C4: =HEX2DEC(MID(B4,10,2)&MID(B4,13,2)) -> 9728 | D4: =HEX2DEC(MID($B4,10+6*D$1,2)&MID($B4,13+6*D$1,2)) -> 0 | E4: =(HEX2DEC(MID($B4,10+6*E$1,2)&MID($B4,13+6*E$1,2))-65536)/100 -> -158.78 | F4: =HEX2DEC(MID($B4,10+6*F$1,2)&MID($B4,13+6*F$1,2)) -> 0 | G4: =HEX2DEC(MID($B4,10+6*G$1,2)&MID($B4,13+6*G$1,2))/10 -> 438.6 | H4: =HEX2DEC(MID($B4,10+6*H$1,2)&MID($B4,13+6*H$1,2)) -> 0 | I4: =HEX2DEC(MID($B4,10+6*I$1,2)&MID($B4,13+6*I$1,2)) -> 0 | J4: =HEX2DEC(MID($B4,10+6*J$1,2)&MID($B4,13+6*J$1,2)) -> 2112 | K4: =HEX2DEC(MID($B4,10+6*K$1,2)&MID($B4,13+6*K$1,2)) -> 18574 | L4: =HEX2DEC(MID($B4,10+6*L$1,2)&MID($B4,13+6*L$1,2))/10 -> 2105.6 | M4: =HEX2DEC(MID($B4,10+6*M$1,2)&MID($B4,13+6*M$1,2)) -> 0 | N4: =(HEX2DEC(MID($B4,10+6*N$1,2)&MID($B4,13+6*N$1,2))-65536)/10 -> -158.7 | O4: =HEX2DEC(MID($B4,10+6*O$1,2)&MID($B4,13+6*O$1,2)) -> 0 | P4: =HEX2DEC(MID($B4,10+6*P$1,2)&MID($B4,13+6*P$1,2)) -> 23444 | Q4: =HEX2DEC(MID($B4,10+6*Q$1,2)&MID($B4,13+6*Q$1,2)) -> 0 | R4: =HEX2DEC(MID($B4,10+6*R$1,2)&MID($B4,13+6*R$1,2)) -> 0 | S4: =VLOOKUP(J4,设备状态表!$D$3:$E$14,2,0) -> 向下运动到固定点监测
A5: [17:16:36.388]收← | B5: 01 03 20 25 9C 00 00 C1 F9 00 00 11 22 00 00 00 00 08 40 48 8E 52 60 00 00 F9 CD 00 00 5B 94 00 00 00 00 A9 3C | C5: =HEX2DEC(MID(B5,10,2)&MID(B5,13,2)) -> 9628 | D5: =HEX2DEC(MID($B5,10+6*D$1,2)&MID($B5,13+6*D$1,2)) -> 0 | E5: =(HEX2DEC(MID($B5,10+6*E$1,2)&MID($B5,13+6*E$1,2))-65536)/100 -> -158.79 | F5: =HEX2DEC(MID($B5,10+6*F$1,2)&MID($B5,13+6*F$1,2)) -> 0 | G5: =HEX2DEC(MID($B5,10+6*G$1,2)&MID($B5,13+6*G$1,2))/10 -> 438.6 | H5: =HEX2DEC(MID($B5,10+6*H$1,2)&MID($B5,13+6*H$1,2)) -> 0 | I5: =HEX2DEC(MID($B5,10+6*I$1,2)&MID($B5,13+6*I$1,2)) -> 0 | J5: =HEX2DEC(MID($B5,10+6*J$1,2)&MID($B5,13+6*J$1,2)) -> 2112 | K5: =HEX2DEC(MID($B5,10+6*K$1,2)&MID($B5,13+6*K$1,2)) -> 18574 | L5: =HEX2DEC(MID($B5,10+6*L$1,2)&MID($B5,13+6*L$1,2))/10 -> 2108.8 | M5: =HEX2DEC(MID($B5,10+6*M$1,2)&MID($B5,13+6*M$1,2)) -> 0 | N5: =(HEX2DEC(MID($B5,10+6*N$1,2)&MID($B5,13+6*N$1,2))-65536)/10 -> -158.7 | O5: =HEX2DEC(MID($B5,10+6*O$1,2)&MID($B5,13+6*O$1,2)) -> 0 | P5: =HEX2DEC(MID($B5,10+6*P$1,2)&MID($B5,13+6*P$1,2)) -> 23444 | Q5: =HEX2DEC(MID($B5,10+6*Q$1,2)&MID($B5,13+6*Q$1,2)) -> 0 | R5: =HEX2DEC(MID($B5,10+6*R$1,2)&MID($B5,13+6*R$1,2)) -> 0 | S5: =VLOOKUP(J5,设备状态表!$D$3:$E$14,2,0) -> 向下运动到固定点监测
A6: [17:16:39.361]收← | B6: 01 03 20 25 3A 00 00 C1 FA 00 00 11 22 00 00 00 00 08 40 48 8E 51 E0 00 00 F9 CD 00 00 5B 94 00 00 00 00 34 60 | C6: =HEX2DEC(MID(B6,10,2)&MID(B6,13,2)) -> 9530 | D6: =HEX2DEC(MID($B6,10+6*D$1,2)&MID($B6,13+6*D$1,2)) -> 0 | E6: =(HEX2DEC(MID($B6,10+6*E$1,2)&MID($B6,13+6*E$1,2))-65536)/100 -> -158.78 | F6: =HEX2DEC(MID($B6,10+6*F$1,2)&MID($B6,13+6*F$1,2)) -> 0 | G6: =HEX2DEC(MID($B6,10+6*G$1,2)&MID($B6,13+6*G$1,2))/10 -> 438.6 | H6: =HEX2DEC(MID($B6,10+6*H$1,2)&MID($B6,13+6*H$1,2)) -> 0 | I6: =HEX2DEC(MID($B6,10+6*I$1,2)&MID($B6,13+6*I$1,2)) -> 0 | J6: =HEX2DEC(MID($B6,10+6*J$1,2)&MID($B6,13+6*J$1,2)) -> 2112 | K6: =HEX2DEC(MID($B6,10+6*K$1,2)&MID($B6,13+6*K$1,2)) -> 18574 | L6: =HEX2DEC(MID($B6,10+6*L$1,2)&MID($B6,13+6*L$1,2))/10 -> 2096 | M6: =HEX2DEC(MID($B6,10+6*M$1,2)&MID($B6,13+6*M$1,2)) -> 0 | N6: =(HEX2DEC(MID($B6,10+6*N$1,2)&MID($B6,13+6*N$1,2))-65536)/10 -> -158.7 | O6: =HEX2DEC(MID($B6,10+6*O$1,2)&MID($B6,13+6*O$1,2)) -> 0 | P6: =HEX2DEC(MID($B6,10+6*P$1,2)&MID($B6,13+6*P$1,2)) -> 23444 | Q6: =HEX2DEC(MID($B6,10+6*Q$1,2)&MID($B6,13+6*Q$1,2)) -> 0 | R6: =HEX2DEC(MID($B6,10+6*R$1,2)&MID($B6,13+6*R$1,2)) -> 0 | S6: =VLOOKUP(J6,设备状态表!$D$3:$E$14,2,0) -> 向下运动到固定点监测
A7: [17:16:47.686]收← | B7: 01 03 20 24 22 00 00 C1 FB 00 00 11 22 00 00 00 00 08 40 48 8E 51 C0 00 00 F9 CD 00 00 5B 94 00 00 00 00 34 23 | C7: =HEX2DEC(MID(B7,10,2)&MID(B7,13,2)) -> 9250 | D7: =HEX2DEC(MID($B7,10+6*D$1,2)&MID($B7,13+6*D$1,2)) -> 0 | E7: =(HEX2DEC(MID($B7,10+6*E$1,2)&MID($B7,13+6*E$1,2))-65536)/100 -> -158.77 | F7: =HEX2DEC(MID($B7,10+6*F$1,2)&MID($B7,13+6*F$1,2)) -> 0 | G7: =HEX2DEC(MID($B7,10+6*G$1,2)&MID($B7,13+6*G$1,2))/10 -> 438.6 | H7: =HEX2DEC(MID($B7,10+6*H$1,2)&MID($B7,13+6*H$1,2)) -> 0 | I7: =HEX2DEC(MID($B7,10+6*I$1,2)&MID($B7,13+6*I$1,2)) -> 0 | J7: =HEX2DEC(MID($B7,10+6*J$1,2)&MID($B7,13+6*J$1,2)) -> 2112 | K7: =HEX2DEC(MID($B7,10+6*K$1,2)&MID($B7,13+6*K$1,2)) -> 18574 | L7: =HEX2DEC(MID($B7,10+6*L$1,2)&MID($B7,13+6*L$1,2))/10 -> 2092.8 | M7: =HEX2DEC(MID($B7,10+6*M$1,2)&MID($B7,13+6*M$1,2)) -> 0 | N7: =(HEX2DEC(MID($B7,10+6*N$1,2)&MID($B7,13+6*N$1,2))-65536)/10 -> -158.7 | O7: =HEX2DEC(MID($B7,10+6*O$1,2)&MID($B7,13+6*O$1,2)) -> 0 | P7: =HEX2DEC(MID($B7,10+6*P$1,2)&MID($B7,13+6*P$1,2)) -> 23444 | Q7: =HEX2DEC(MID($B7,10+6*Q$1,2)&MID($B7,13+6*Q$1,2)) -> 0 | R7: =HEX2DEC(MID($B7,10+6*R$1,2)&MID($B7,13+6*R$1,2)) -> 0 | S7: =VLOOKUP(J7,设备状态表!$D$3:$E$14,2,0) -> 向下运动到固定点监测
A8: [17:16:49.248]收← | B8: 01 03 20 23 EE 00 00 C1 FB 00 00 11 22 00 00 00 00 08 40 48 8E 52 60 00 00 F9 CD 00 00 5B 94 00 00 00 00 75 6F | C8: =HEX2DEC(MID(B8,10,2)&MID(B8,13,2)) -> 9198 | D8: =HEX2DEC(MID($B8,10+6*D$1,2)&MID($B8,13+6*D$1,2)) -> 0 | E8: =(HEX2DEC(MID($B8,10+6*E$1,2)&MID($B8,13+6*E$1,2))-65536)/100 -> -158.77 | F8: =HEX2DEC(MID($B8,10+6*F$1,2)&MID($B8,13+6*F$1,2)) -> 0 | G8: =HEX2DEC(MID($B8,10+6*G$1,2)&MID($B8,13+6*G$1,2))/10 -> 438.6 | H8: =HEX2DEC(MID($B8,10+6*H$1,2)&MID($B8,13+6*H$1,2)) -> 0 | I8: =HEX2DEC(MID($B8,10+6*I$1,2)&MID($B8,13+6*I$1,2)) -> 0 | J8: =HEX2DEC(MID($B8,10+6*J$1,2)&MID($B8,13+6*J$1,2)) -> 2112 | K8: =HEX2DEC(MID($B8,10+6*K$1,2)&MID($B8,13+6*K$1,2)) -> 18574 | L8: =HEX2DEC(MID($B8,10+6*L$1,2)&MID($B8,13+6*L$1,2))/10 -> 2108.8 | M8: =HEX2DEC(MID($B8,10+6*M$1,2)&MID($B8,13+6*M$1,2)) -> 0 | N8: =(HEX2DEC(MID($B8,10+6*N$1,2)&MID($B8,13+6*N$1,2))-65536)/10 -> -158.7 | O8: =HEX2DEC(MID($B8,10+6*O$1,2)&MID($B8,13+6*O$1,2)) -> 0 | P8: =HEX2DEC(MID($B8,10+6*P$1,2)&MID($B8,13+6*P$1,2)) -> 23444 | Q8: =HEX2DEC(MID($B8,10+6*Q$1,2)&MID($B8,13+6*Q$1,2)) -> 0 | R8: =HEX2DEC(MID($B8,10+6*R$1,2)&MID($B8,13+6*R$1,2)) -> 0 | S8: =VLOOKUP(J8,设备状态表!$D$3:$E$14,2,0) -> 向下运动到固定点监测
A9: [17:16:52.302]收← | B9: 01 03 20 23 87 00 00 C1 FA 00 00 11 22 00 00 00 00 08 40 48 8E 51 A0 00 00 F9 CD 00 00 5B 94 00 00 00 00 99 DD | C9: =HEX2DEC(MID(B9,10,2)&MID(B9,13,2)) -> 9095 | D9: =HEX2DEC(MID($B9,10+6*D$1,2)&MID($B9,13+6*D$1,2)) -> 0 | E9: =(HEX2DEC(MID($B9,10+6*E$1,2)&MID($B9,13+6*E$1,2))-65536)/100 -> -158.78 | F9: =HEX2DEC(MID($B9,10+6*F$1,2)&MID($B9,13+6*F$1,2)) -> 0 | G9: =HEX2DEC(MID($B9,10+6*G$1,2)&MID($B9,13+6*G$1,2))/10 -> 438.6 | H9: =HEX2DEC(MID($B9,10+6*H$1,2)&MID($B9,13+6*H$1,2)) -> 0 | I9: =HEX2DEC(MID($B9,10+6*I$1,2)&MID($B9,13+6*I$1,2)) -> 0 | J9: =HEX2DEC(MID($B9,10+6*J$1,2)&MID($B9,13+6*J$1,2)) -> 2112 | K9: =HEX2DEC(MID($B9,10+6*K$1,2)&MID($B9,13+6*K$1,2)) -> 18574 | L9: =HEX2DEC(MID($B9,10+6*L$1,2)&MID($B9,13+6*L$1,2))/10 -> 2089.6 | M9: =HEX2DEC(MID($B9,10+6*M$1,2)&MID($B9,13+6*M$1,2)) -> 0 | N9: =(HEX2DEC(MID($B9,10+6*N$1,2)&MID($B9,13+6*N$1,2))-65536)/10 -> -158.7 | O9: =HEX2DEC(MID($B9,10+6*O$1,2)&MID($B9,13+6*O$1,2)) -> 0 | P9: =HEX2DEC(MID($B9,10+6*P$1,2)&MID($B9,13+6*P$1,2)) -> 23444 | Q9: =HEX2DEC(MID($B9,10+6*Q$1,2)&MID($B9,13+6*Q$1,2)) -> 0 | R9: =HEX2DEC(MID($B9,10+6*R$1,2)&MID($B9,13+6*R$1,2)) -> 0 | S9: =VLOOKUP(J9,设备状态表!$D$3:$E$14,2,0) -> 向下运动到固定点监测
A10: [17:16:55.298]收← | B10: 01 03 20 23 23 00 00 C1 FA 00 00 11 22 00 00 00 00 08 40 48 8E 52 20 00 00 F9 CD 00 00 5B 94 00 00 00 00 24 87 | C10: =HEX2DEC(MID(B10,10,2)&MID(B10,13,2)) -> 8995 | D10: =HEX2DEC(MID($B10,10+6*D$1,2)&MID($B10,13+6*D$1,2)) -> 0 | E10: =(HEX2DEC(MID($B10,10+6*E$1,2)&MID($B10,13+6*E$1,2))-65536)/100 -> -158.78 | F10: =HEX2DEC(MID($B10,10+6*F$1,2)&MID($B10,13+6*F$1,2)) -> 0 | G10: =HEX2DEC(MID($B10,10+6*G$1,2)&MID($B10,13+6*G$1,2))/10 -> 438.6 | H10: =HEX2DEC(MID($B10,10+6*H$1,2)&MID($B10,13+6*H$1,2)) -> 0 | I10: =HEX2DEC(MID($B10,10+6*I$1,2)&MID($B10,13+6*I$1,2)) -> 0 | J10: =HEX2DEC(MID($B10,10+6*J$1,2)&MID($B10,13+6*J$1,2)) -> 2112 | K10: =HEX2DEC(MID($B10,10+6*K$1,2)&MID($B10,13+6*K$1,2)) -> 18574 | L10: =HEX2DEC(MID($B10,10+6*L$1,2)&MID($B10,13+6*L$1,2))/10 -> 2102.4 | M10: =HEX2DEC(MID($B10,10+6*M$1,2)&MID($B10,13+6*M$1,2)) -> 0 | N10: =(HEX2DEC(MID($B10,10+6*N$1,2)&MID($B10,13+6*N$1,2))-65536)/10 -> -158.7 | O10: =HEX2DEC(MID($B10,10+6*O$1,2)&MID($B10,13+6*O$1,2)) -> 0 | P10: =HEX2DEC(MID($B10,10+6*P$1,2)&MID($B10,13+6*P$1,2)) -> 23444 | Q10: =HEX2DEC(MID($B10,10+6*Q$1,2)&MID($B10,13+6*Q$1,2)) -> 0 | R10: =HEX2DEC(MID($B10,10+6*R$1,2)&MID($B10,13+6*R$1,2)) -> 0 | S10: =VLOOKUP(J10,设备状态表!$D$3:$E$14,2,0) -> 向下运动到固定点监测
A11: [17:16:58.270]收← | B11: 01 03 20 22 C1 00 00 C1 FA 00 00 11 22 00 00 00 00 08 40 48 8E 51 40 00 00 F9 CD 00 00 5B 94 00 00 00 00 87 F7 | C11: =HEX2DEC(MID(B11,10,2)&MID(B11,13,2)) -> 8897 | D11: =HEX2DEC(MID($B11,10+6*D$1,2)&MID($B11,13+6*D$1,2)) -> 0 | E11: =(HEX2DEC(MID($B11,10+6*E$1,2)&MID($B11,13+6*E$1,2))-65536)/100 -> -158.78 | F11: =HEX2DEC(MID($B11,10+6*F$1,2)&MID($B11,13+6*F$1,2)) -> 0 | G11: =HEX2DEC(MID($B11,10+6*G$1,2)&MID($B11,13+6*G$1,2))/10 -> 438.6 | H11: =HEX2DEC(MID($B11,10+6*H$1,2)&MID($B11,13+6*H$1,2)) -> 0 | I11: =HEX2DEC(MID($B11,10+6*I$1,2)&MID($B11,13+6*I$1,2)) -> 0 | J11: =HEX2DEC(MID($B11,10+6*J$1,2)&MID($B11,13+6*J$1,2)) -> 2112 | K11: =HEX2DEC(MID($B11,10+6*K$1,2)&MID($B11,13+6*K$1,2)) -> 18574 | L11: =HEX2DEC(MID($B11,10+6*L$1,2)&MID($B11,13+6*L$1,2))/10 -> 2080 | M11: =HEX2DEC(MID($B11,10+6*M$1,2)&MID($B11,13+6*M$1,2)) -> 0 | N11: =(HEX2DEC(MID($B11,10+6*N$1,2)&MID($B11,13+6*N$1,2))-65536)/10 -> -158.7 | O11: =HEX2DEC(MID($B11,10+6*O$1,2)&MID($B11,13+6*O$1,2)) -> 0 | P11: =HEX2DEC(MID($B11,10+6*P$1,2)&MID($B11,13+6*P$1,2)) -> 23444 | Q11: =HEX2DEC(MID($B11,10+6*Q$1,2)&MID($B11,13+6*Q$1,2)) -> 0 | R11: =HEX2DEC(MID($B11,10+6*R$1,2)&MID($B11,13+6*R$1,2)) -> 0 | S11: =VLOOKUP(J11,设备状态表!$D$3:$E$14,2,0) -> 向下运动到固定点监测
A12: [17:17:01.338]收← | B12: 01 03 20 22 5B 00 00 C1 FA 00 00 11 22 00 00 00 00 08 40 48 8E 51 80 00 00 F9 CD 00 00 5B 94 00 00 00 00 26 B2 | C12: =HEX2DEC(MID(B12,10,2)&MID(B12,13,2)) -> 8795 | D12: =HEX2DEC(MID($B12,10+6*D$1,2)&MID($B12,13+6*D$1,2)) -> 0 | E12: =(HEX2DEC(MID($B12,10+6*E$1,2)&MID($B12,13+6*E$1,2))-65536)/100 -> -158.78 | F12: =HEX2DEC(MID($B12,10+6*F$1,2)&MID($B12,13+6*F$1,2)) -> 0 | G12: =HEX2DEC(MID($B12,10+6*G$1,2)&MID($B12,13+6*G$1,2))/10 -> 438.6 | H12: =HEX2DEC(MID($B12,10+6*H$1,2)&MID($B12,13+6*H$1,2)) -> 0 | I12: =HEX2DEC(MID($B12,10+6*I$1,2)&MID($B12,13+6*I$1,2)) -> 0 | J12: =HEX2DEC(MID($B12,10+6*J$1,2)&MID($B12,13+6*J$1,2)) -> 2112 | K12: =HEX2DEC(MID($B12,10+6*K$1,2)&MID($B12,13+6*K$1,2)) -> 18574 | L12: =HEX2DEC(MID($B12,10+6*L$1,2)&MID($B12,13+6*L$1,2))/10 -> 2086.4 | M12: =HEX2DEC(MID($B12,10+6*M$1,2)&MID($B12,13+6*M$1,2)) -> 0 | N12: =(HEX2DEC(MID($B12,10+6*N$1,2)&MID($B12,13+6*N$1,2))-65536)/10 -> -158.7 | O12: =HEX2DEC(MID($B12,10+6*O$1,2)&MID($B12,13+6*O$1,2)) -> 0 | P12: =HEX2DEC(MID($B12,10+6*P$1,2)&MID($B12,13+6*P$1,2)) -> 23444 | Q12: =HEX2DEC(MID($B12,10+6*Q$1,2)&MID($B12,13+6*Q$1,2)) -> 0 | R12: =HEX2DEC(MID($B12,10+6*R$1,2)&MID($B12,13+6*R$1,2)) -> 0 | S12: =VLOOKUP(J12,设备状态表!$D$3:$E$14,2,0) -> 向下运动到固定点监测
A13: [17:17:04.241]收← | B13: 01 03 20 21 FA 00 00 C1 FB 00 00 11 22 00 00 00 00 08 40 48 8E 51 E0 00 00 F9 CD 00 00 5B 94 00 00 00 00 C8 BE | C13: =HEX2DEC(MID(B13,10,2)&MID(B13,13,2)) -> 8698 | D13: =HEX2DEC(MID($B13,10+6*D$1,2)&MID($B13,13+6*D$1,2)) -> 0 | E13: =(HEX2DEC(MID($B13,10+6*E$1,2)&MID($B13,13+6*E$1,2))-65536)/100 -> -158.77 | F13: =HEX2DEC(MID($B13,10+6*F$1,2)&MID($B13,13+6*F$1,2)) -> 0 | G13: =HEX2DEC(MID($B13,10+6*G$1,2)&MID($B13,13+6*G$1,2))/10 -> 438.6 | H13: =HEX2DEC(MID($B13,10+6*H$1,2)&MID($B13,13+6*H$1,2)) -> 0 | I13: =HEX2DEC(MID($B13,10+6*I$1,2)&MID($B13,13+6*I$1,2)) -> 0 | J13: =HEX2DEC(MID($B13,10+6*J$1,2)&MID($B13,13+6*J$1,2)) -> 2112 | K13: =HEX2DEC(MID($B13,10+6*K$1,2)&MID($B13,13+6*K$1,2)) -> 18574 | L13: =HEX2DEC(MID($B13,10+6*L$1,2)&MID($B13,13+6*L$1,2))/10 -> 2096 | M13: =HEX2DEC(MID($B13,10+6*M$1,2)&MID($B13,13+6*M$1,2)) -> 0 | N13: =(HEX2DEC(MID($B13,10+6*N$1,2)&MID($B13,13+6*N$1,2))-65536)/10 -> -158.7 | O13: =HEX2DEC(MID($B13,10+6*O$1,2)&MID($B13,13+6*O$1,2)) -> 0 | P13: =HEX2DEC(MID($B13,10+6*P$1,2)&MID($B13,13+6*P$1,2)) -> 23444 | Q13: =HEX2DEC(MID($B13,10+6*Q$1,2)&MID($B13,13+6*Q$1,2)) -> 0 | R13: =HEX2DEC(MID($B13,10+6*R$1,2)&MID($B13,13+6*R$1,2)) -> 0 | S13: =VLOOKUP(J13,设备状态表!$D$3:$E$14,2,0) -> 向下运动到固定点监测
A14: [17:17:08.267]收← | B14: 01 03 20 21 73 00 00 C1 FA 00 00 11 22 00 00 00 00 08 40 48 8E 52 80 00 00 F9 CD 00 00 5B 94 00 00 00 00 A5 13 | C14: =HEX2DEC(MID(B14,10,2)&MID(B14,13,2)) -> 8563 | D14: =HEX2DEC(MID($B14,10+6*D$1,2)&MID($B14,13+6*D$1,2)) -> 0 | E14: =(HEX2DEC(MID($B14,10+6*E$1,2)&MID($B14,13+6*E$1,2))-65536)/100 -> -158.78 | F14: =HEX2DEC(MID($B14,10+6*F$1,2)&MID($B14,13+6*F$1,2)) -> 0 | G14: =HEX2DEC(MID($B14,10+6*G$1,2)&MID($B14,13+6*G$1,2))/10 -> 438.6 | H14: =HEX2DEC(MID($B14,10+6*H$1,2)&MID($B14,13+6*H$1,2)) -> 0 | I14: =HEX2DEC(MID($B14,10+6*I$1,2)&MID($B14,13+6*I$1,2)) -> 0 | J14: =HEX2DEC(MID($B14,10+6*J$1,2)&MID($B14,13+6*J$1,2)) -> 2112 | K14: =HEX2DEC(MID($B14,10+6*K$1,2)&MID($B14,13+6*K$1,2)) -> 18574 | L14: =HEX2DEC(MID($B14,10+6*L$1,2)&MID($B14,13+6*L$1,2))/10 -> 2112 | M14: =HEX2DEC(MID($B14,10+6*M$1,2)&MID($B14,13+6*M$1,2)) -> 0 | N14: =(HEX2DEC(MID($B14,10+6*N$1,2)&MID($B14,13+6*N$1,2))-65536)/10 -> -158.7 | O14: =HEX2DEC(MID($B14,10+6*O$1,2)&MID($B14,13+6*O$1,2)) -> 0 | P14: =HEX2DEC(MID($B14,10+6*P$1,2)&MID($B14,13+6*P$1,2)) -> 23444 | Q14: =HEX2DEC(MID($B14,10+6*Q$1,2)&MID($B14,13+6*Q$1,2)) -> 0 | R14: =HEX2DEC(MID($B14,10+6*R$1,2)&MID($B14,13+6*R$1,2)) -> 0 | S14: =VLOOKUP(J14,设备状态表!$D$3:$E$14,2,0) -> 向下运动到固定点监测
A15: [17:17:11.424]收← | B15: 01 03 20 21 09 00 00 C1 FA 00 00 11 22 00 00 00 00 08 40 48 8E 51 E0 00 00 F9 CD 00 00 5B 94 00 00 00 00 86 4A | C15: =HEX2DEC(MID(B15,10,2)&MID(B15,13,2)) -> 8457 | D15: =HEX2DEC(MID($B15,10+6*D$1,2)&MID($B15,13+6*D$1,2)) -> 0 | E15: =(HEX2DEC(MID($B15,10+6*E$1,2)&MID($B15,13+6*E$1,2))-65536)/100 -> -158.78 | F15: =HEX2DEC(MID($B15,10+6*F$1,2)&MID($B15,13+6*F$1,2)) -> 0 | G15: =HEX2DEC(MID($B15,10+6*G$1,2)&MID($B15,13+6*G$1,2))/10 -> 438.6 | H15: =HEX2DEC(MID($B15,10+6*H$1,2)&MID($B15,13+6*H$1,2)) -> 0 | I15: =HEX2DEC(MID($B15,10+6*I$1,2)&MID($B15,13+6*I$1,2)) -> 0 | J15: =HEX2DEC(MID($B15,10+6*J$1,2)&MID($B15,13+6*J$1,2)) -> 2112 | K15: =HEX2DEC(MID($B15,10+6*K$1,2)&MID($B15,13+6*K$1,2)) -> 18574 | L15: =HEX2DEC(MID($B15,10+6*L$1,2)&MID($B15,13+6*L$1,2))/10 -> 2096 | M15: =HEX2DEC(MID($B15,10+6*M$1,2)&MID($B15,13+6*M$1,2)) -> 0 | N15: =(HEX2DEC(MID($B15,10+6*N$1,2)&MID($B15,13+6*N$1,2))-65536)/10 -> -158.7 | O15: =HEX2DEC(MID($B15,10+6*O$1,2)&MID($B15,13+6*O$1,2)) -> 0 | P15: =HEX2DEC(MID($B15,10+6*P$1,2)&MID($B15,13+6*P$1,2)) -> 23444 | Q15: =HEX2DEC(MID($B15,10+6*Q$1,2)&MID($B15,13+6*Q$1,2)) -> 0 | R15: =HEX2DEC(MID($B15,10+6*R$1,2)&MID($B15,13+6*R$1,2)) -> 0 | S15: =VLOOKUP(J15,设备状态表!$D$3:$E$14,2,0) -> 向下运动到固定点监测
... A299: [17:33:34.843]收← | B299: 01 03 20 5B 98 00 00 C1 FB 00 00 11 1B 00 00 00 00 0C 60 48 8D AC 40 00 00 F9 CD 00 00 5B 94 00 00 00 00 48 B8 | C299: =HEX2DEC(MID(B299,10,2)&MID(B299,13,2)) -> 23448 | D299: =HEX2DEC(MID($B299,10+6*D$1,2)&MID($B299,13+6*D$1,2)) -> 0 | E299: =(HEX2DEC(MID($B299,10+6*E$1,2)&MID($B299,13+6*E$1,2))-65536)/100 -> -158.77 | F299: =HEX2DEC(MID($B299,10+6*F$1,2)&MID($B299,13+6*F$1,2)) -> 0 | G299: =HEX2DEC(MID($B299,10+6*G$1,2)&MID($B299,13+6*G$1,2))/10 -> 437.9 | H299: =HEX2DEC(MID($B299,10+6*H$1,2)&MID($B299,13+6*H$1,2)) -> 0 | I299: =HEX2DEC(MID($B299,10+6*I$1,2)&MID($B299,13+6*I$1,2)) -> 0 | J299: =HEX2DEC(MID($B299,10+6*J$1,2)&MID($B299,13+6*J$1,2)) -> 3168 | K299: =HEX2DEC(MID($B299,10+6*K$1,2)&MID($B299,13+6*K$1,2)) -> 18573 | L299: =HEX2DEC(MID($B299,10+6*L$1,2)&MID($B299,13+6*L$1,2))/10 -> 4409.6 | M299: =HEX2DEC(MID($B299,10+6*M$1,2)&MID($B299,13+6*M$1,2)) -> 0 | N299: =(HEX2DEC(MID($B299,10+6*N$1,2)&MID($B299,13+6*N$1,2))-65536)/10 -> -158.7 | O299: =HEX2DEC(MID($B299,10+6*O$1,2)&MID($B299,13+6*O$1,2)) -> 0 | P299: =HEX2DEC(MID($B299,10+6*P$1,2)&MID($B299,13+6*P$1,2)) -> 23444 | Q299: =HEX2DEC(MID($B299,10+6*Q$1,2)&MID($B299,13+6*Q$1,2)) -> 0 | R299: =HEX2DEC(MID($B299,10+6*R$1,2)&MID($B299,13+6*R$1,2)) -> 0 | S299: =VLOOKUP(J299,设备状态表!$D$3:$E$14,2,0) -> 向上运行，密度分布测量中
A300: [17:33:37.940]收← | B300: 01 03 20 5B 9D 00 00 C1 F9 00 00 0B 3E 00 00 00 00 18 40 48 7B CB 40 00 00 F9 CD 00 00 5B 98 00 00 00 00 CD 42 | C300: =HEX2DEC(MID(B300,10,2)&MID(B300,13,2)) -> 23453 | D300: =HEX2DEC(MID($B300,10+6*D$1,2)&MID($B300,13+6*D$1,2)) -> 0 | E300: =(HEX2DEC(MID($B300,10+6*E$1,2)&MID($B300,13+6*E$1,2))-65536)/100 -> -158.79 | F300: =HEX2DEC(MID($B300,10+6*F$1,2)&MID($B300,13+6*F$1,2)) -> 0 | G300: =HEX2DEC(MID($B300,10+6*G$1,2)&MID($B300,13+6*G$1,2))/10 -> 287.8 | H300: =HEX2DEC(MID($B300,10+6*H$1,2)&MID($B300,13+6*H$1,2)) -> 0 | I300: =HEX2DEC(MID($B300,10+6*I$1,2)&MID($B300,13+6*I$1,2)) -> 0 | J300: =HEX2DEC(MID($B300,10+6*J$1,2)&MID($B300,13+6*J$1,2)) -> 6208 | K300: =HEX2DEC(MID($B300,10+6*K$1,2)&MID($B300,13+6*K$1,2)) -> 18555 | L300: =HEX2DEC(MID($B300,10+6*L$1,2)&MID($B300,13+6*L$1,2))/10 -> 5203.2 | M300: =HEX2DEC(MID($B300,10+6*M$1,2)&MID($B300,13+6*M$1,2)) -> 0 | N300: =(HEX2DEC(MID($B300,10+6*N$1,2)&MID($B300,13+6*N$1,2))-65536)/10 -> -158.7 | O300: =HEX2DEC(MID($B300,10+6*O$1,2)&MID($B300,13+6*O$1,2)) -> 0 | P300: =HEX2DEC(MID($B300,10+6*P$1,2)&MID($B300,13+6*P$1,2)) -> 23448 | Q300: =HEX2DEC(MID($B300,10+6*Q$1,2)&MID($B300,13+6*Q$1,2)) -> 0 | R300: =HEX2DEC(MID($B300,10+6*R$1,2)&MID($B300,13+6*R$1,2)) -> 0 | S300: =VLOOKUP(J300,设备状态表!$D$3:$E$14,2,0) -> 下行到最低点，界面附近 | T300: 下一个包读密度
A301: [17:33:39.869]收← | B301: 01 03 20 5B 8D 00 00 C1 F9 00 00 0F F3 00 00 00 00 18 40 48 87 22 00 00 00 F9 CD 00 00 5B 98 00 00 00 00 90 6A | C301: =HEX2DEC(MID(B301,10,2)&MID(B301,13,2)) -> 23437 | D301: =HEX2DEC(MID($B301,10+6*D$1,2)&MID($B301,13+6*D$1,2)) -> 0 | E301: =(HEX2DEC(MID($B301,10+6*E$1,2)&MID($B301,13+6*E$1,2))-65536)/100 -> -158.79 | F301: =HEX2DEC(MID($B301,10+6*F$1,2)&MID($B301,13+6*F$1,2)) -> 0 | G301: =HEX2DEC(MID($B301,10+6*G$1,2)&MID($B301,13+6*G$1,2))/10 -> 408.3 | H301: =HEX2DEC(MID($B301,10+6*H$1,2)&MID($B301,13+6*H$1,2)) -> 0 | I301: =HEX2DEC(MID($B301,10+6*I$1,2)&MID($B301,13+6*I$1,2)) -> 0 | J301: =HEX2DEC(MID($B301,10+6*J$1,2)&MID($B301,13+6*J$1,2)) -> 6208 | K301: =HEX2DEC(MID($B301,10+6*K$1,2)&MID($B301,13+6*K$1,2)) -> 18567 | L301: =HEX2DEC(MID($B301,10+6*L$1,2)&MID($B301,13+6*L$1,2))/10 -> 870.4 | M301: =HEX2DEC(MID($B301,10+6*M$1,2)&MID($B301,13+6*M$1,2)) -> 0 | N301: =(HEX2DEC(MID($B301,10+6*N$1,2)&MID($B301,13+6*N$1,2))-65536)/10 -> -158.7 | O301: =HEX2DEC(MID($B301,10+6*O$1,2)&MID($B301,13+6*O$1,2)) -> 0 | P301: =HEX2DEC(MID($B301,10+6*P$1,2)&MID($B301,13+6*P$1,2)) -> 23448 | Q301: =HEX2DEC(MID($B301,10+6*Q$1,2)&MID($B301,13+6*Q$1,2)) -> 0 | R301: =HEX2DEC(MID($B301,10+6*R$1,2)&MID($B301,13+6*R$1,2)) -> 0 | S301: =VLOOKUP(J301,设备状态表!$D$3:$E$14,2,0) -> 下行到最低点，界面附近
A302: [17:33:48.749]收← | B302: 01 03 20 5A 8D 00 00 C1 F9 00 00 11 24 00 00 00 00 08 40 48 8E 56 C0 00 00 F9 CD 00 00 5B 98 00 00 00 00 3F FF | C302: =HEX2DEC(MID(B302,10,2)&MID(B302,13,2)) -> 23181 | D302: =HEX2DEC(MID($B302,10+6*D$1,2)&MID($B302,13+6*D$1,2)) -> 0 | E302: =(HEX2DEC(MID($B302,10+6*E$1,2)&MID($B302,13+6*E$1,2))-65536)/100 -> -158.79 | F302: =HEX2DEC(MID($B302,10+6*F$1,2)&MID($B302,13+6*F$1,2)) -> 0 | G302: =HEX2DEC(MID($B302,10+6*G$1,2)&MID($B302,13+6*G$1,2))/10 -> 438.8 | H302: =HEX2DEC(MID($B302,10+6*H$1,2)&MID($B302,13+6*H$1,2)) -> 0 | I302: =HEX2DEC(MID($B302,10+6*I$1,2)&MID($B302,13+6*I$1,2)) -> 0 | J302: =HEX2DEC(MID($B302,10+6*J$1,2)&MID($B302,13+6*J$1,2)) -> 2112 | K302: =HEX2DEC(MID($B302,10+6*K$1,2)&MID($B302,13+6*K$1,2)) -> 18574 | L302: =HEX2DEC(MID($B302,10+6*L$1,2)&MID($B302,13+6*L$1,2))/10 -> 2220.8 | M302: =HEX2DEC(MID($B302,10+6*M$1,2)&MID($B302,13+6*M$1,2)) -> 0 | N302: =(HEX2DEC(MID($B302,10+6*N$1,2)&MID($B302,13+6*N$1,2))-65536)/10 -> -158.7 | O302: =HEX2DEC(MID($B302,10+6*O$1,2)&MID($B302,13+6*O$1,2)) -> 0 | P302: =HEX2DEC(MID($B302,10+6*P$1,2)&MID($B302,13+6*P$1,2)) -> 23448 | Q302: =HEX2DEC(MID($B302,10+6*Q$1,2)&MID($B302,13+6*Q$1,2)) -> 0 | R302: =HEX2DEC(MID($B302,10+6*R$1,2)&MID($B302,13+6*R$1,2)) -> 0 | S302: =VLOOKUP(J302,设备状态表!$D$3:$E$14,2,0) -> 向下运动到固定点监测
A303: [17:33:51.826]收← | B303: 01 03 20 5A 27 00 00 C1 F8 00 00 11 24 00 00 00 00 08 40 48 8E 55 A0 00 00 F9 CD 00 00 5B 98 00 00 00 00 E3 81 | C303: =HEX2DEC(MID(B303,10,2)&MID(B303,13,2)) -> 23079 | D303: =HEX2DEC(MID($B303,10+6*D$1,2)&MID($B303,13+6*D$1,2)) -> 0 | E303: =(HEX2DEC(MID($B303,10+6*E$1,2)&MID($B303,13+6*E$1,2))-65536)/100 -> -158.8 | F303: =HEX2DEC(MID($B303,10+6*F$1,2)&MID($B303,13+6*F$1,2)) -> 0 | G303: =HEX2DEC(MID($B303,10+6*G$1,2)&MID($B303,13+6*G$1,2))/10 -> 438.8 | H303: =HEX2DEC(MID($B303,10+6*H$1,2)&MID($B303,13+6*H$1,2)) -> 0 | I303: =HEX2DEC(MID($B303,10+6*I$1,2)&MID($B303,13+6*I$1,2)) -> 0 | J303: =HEX2DEC(MID($B303,10+6*J$1,2)&MID($B303,13+6*J$1,2)) -> 2112 | K303: =HEX2DEC(MID($B303,10+6*K$1,2)&MID($B303,13+6*K$1,2)) -> 18574 | L303: =HEX2DEC(MID($B303,10+6*L$1,2)&MID($B303,13+6*L$1,2))/10 -> 2192 | M303: =HEX2DEC(MID($B303,10+6*M$1,2)&MID($B303,13+6*M$1,2)) -> 0 | N303: =(HEX2DEC(MID($B303,10+6*N$1,2)&MID($B303,13+6*N$1,2))-65536)/10 -> -158.7 | O303: =HEX2DEC(MID($B303,10+6*O$1,2)&MID($B303,13+6*O$1,2)) -> 0 | P303: =HEX2DEC(MID($B303,10+6*P$1,2)&MID($B303,13+6*P$1,2)) -> 23448 | Q303: =HEX2DEC(MID($B303,10+6*Q$1,2)&MID($B303,13+6*Q$1,2)) -> 0 | R303: =HEX2DEC(MID($B303,10+6*R$1,2)&MID($B303,13+6*R$1,2)) -> 0 | S303: =VLOOKUP(J303,设备状态表!$D$3:$E$14,2,0) -> 向下运动到固定点监测
A304: [17:33:54.801]收← | B304: 01 03 20 59 C6 00 00 C1 F9 00 00 11 24 00 00 00 00 08 40 48 8E 56 60 00 00 F9 CD 00 00 5B 98 00 00 00 00 8F CB | C304: =HEX2DEC(MID(B304,10,2)&MID(B304,13,2)) -> 22982 | D304: =HEX2DEC(MID($B304,10+6*D$1,2)&MID($B304,13+6*D$1,2)) -> 0 | E304: =(HEX2DEC(MID($B304,10+6*E$1,2)&MID($B304,13+6*E$1,2))-65536)/100 -> -158.79 | F304: =HEX2DEC(MID($B304,10+6*F$1,2)&MID($B304,13+6*F$1,2)) -> 0 | G304: =HEX2DEC(MID($B304,10+6*G$1,2)&MID($B304,13+6*G$1,2))/10 -> 438.8 | H304: =HEX2DEC(MID($B304,10+6*H$1,2)&MID($B304,13+6*H$1,2)) -> 0 | I304: =HEX2DEC(MID($B304,10+6*I$1,2)&MID($B304,13+6*I$1,2)) -> 0 | J304: =HEX2DEC(MID($B304,10+6*J$1,2)&MID($B304,13+6*J$1,2)) -> 2112 | K304: =HEX2DEC(MID($B304,10+6*K$1,2)&MID($B304,13+6*K$1,2)) -> 18574 | L304: =HEX2DEC(MID($B304,10+6*L$1,2)&MID($B304,13+6*L$1,2))/10 -> 2211.2 | M304: =HEX2DEC(MID($B304,10+6*M$1,2)&MID($B304,13+6*M$1,2)) -> 0 | N304: =(HEX2DEC(MID($B304,10+6*N$1,2)&MID($B304,13+6*N$1,2))-65536)/10 -> -158.7 | O304: =HEX2DEC(MID($B304,10+6*O$1,2)&MID($B304,13+6*O$1,2)) -> 0 | P304: =HEX2DEC(MID($B304,10+6*P$1,2)&MID($B304,13+6*P$1,2)) -> 23448 | Q304: =HEX2DEC(MID($B304,10+6*Q$1,2)&MID($B304,13+6*Q$1,2)) -> 0 | R304: =HEX2DEC(MID($B304,10+6*R$1,2)&MID($B304,13+6*R$1,2)) -> 0 | S304: =VLOOKUP(J304,设备状态表!$D$3:$E$14,2,0) -> 向下运动到固定点监测
A305: [17:33:58.816]收← | B305: 01 03 20 59 41 00 00 C1 FA 00 00 11 24 00 00 00 00 08 40 48 8E 55 C0 00 00 F9 CD 00 00 5B 98 00 00 00 00 FD E5 | C305: =HEX2DEC(MID(B305,10,2)&MID(B305,13,2)) -> 22849 | D305: =HEX2DEC(MID($B305,10+6*D$1,2)&MID($B305,13+6*D$1,2)) -> 0 | E305: =(HEX2DEC(MID($B305,10+6*E$1,2)&MID($B305,13+6*E$1,2))-65536)/100 -> -158.78 | F305: =HEX2DEC(MID($B305,10+6*F$1,2)&MID($B305,13+6*F$1,2)) -> 0 | G305: =HEX2DEC(MID($B305,10+6*G$1,2)&MID($B305,13+6*G$1,2))/10 -> 438.8 | H305: =HEX2DEC(MID($B305,10+6*H$1,2)&MID($B305,13+6*H$1,2)) -> 0 | I305: =HEX2DEC(MID($B305,10+6*I$1,2)&MID($B305,13+6*I$1,2)) -> 0 | J305: =HEX2DEC(MID($B305,10+6*J$1,2)&MID($B305,13+6*J$1,2)) -> 2112 | K305: =HEX2DEC(MID($B305,10+6*K$1,2)&MID($B305,13+6*K$1,2)) -> 18574 | L305: =HEX2DEC(MID($B305,10+6*L$1,2)&MID($B305,13+6*L$1,2))/10 -> 2195.2 | M305: =HEX2DEC(MID($B305,10+6*M$1,2)&MID($B305,13+6*M$1,2)) -> 0 | N305: =(HEX2DEC(MID($B305,10+6*N$1,2)&MID($B305,13+6*N$1,2))-65536)/10 -> -158.7 | O305: =HEX2DEC(MID($B305,10+6*O$1,2)&MID($B305,13+6*O$1,2)) -> 0 | P305: =HEX2DEC(MID($B305,10+6*P$1,2)&MID($B305,13+6*P$1,2)) -> 23448 | Q305: =HEX2DEC(MID($B305,10+6*Q$1,2)&MID($B305,13+6*Q$1,2)) -> 0 | R305: =HEX2DEC(MID($B305,10+6*R$1,2)&MID($B305,13+6*R$1,2)) -> 0 | S305: =VLOOKUP(J305,设备状态表!$D$3:$E$14,2,0) -> 向下运动到固定点监测
A306: [17:34:00.857]收← | B306: 01 03 20 58 FE 00 00 C1 FA 00 00 11 24 00 00 00 00 08 40 48 8E 56 C0 00 00 F9 CD 00 00 5B 98 00 00 00 00 8E DE | C306: =HEX2DEC(MID(B306,10,2)&MID(B306,13,2)) -> 22782 | D306: =HEX2DEC(MID($B306,10+6*D$1,2)&MID($B306,13+6*D$1,2)) -> 0 | E306: =(HEX2DEC(MID($B306,10+6*E$1,2)&MID($B306,13+6*E$1,2))-65536)/100 -> -158.78 | F306: =HEX2DEC(MID($B306,10+6*F$1,2)&MID($B306,13+6*F$1,2)) -> 0 | G306: =HEX2DEC(MID($B306,10+6*G$1,2)&MID($B306,13+6*G$1,2))/10 -> 438.8 | H306: =HEX2DEC(MID($B306,10+6*H$1,2)&MID($B306,13+6*H$1,2)) -> 0 | I306: =HEX2DEC(MID($B306,10+6*I$1,2)&MID($B306,13+6*I$1,2)) -> 0 | J306: =HEX2DEC(MID($B306,10+6*J$1,2)&MID($B306,13+6*J$1,2)) -> 2112 | K306: =HEX2DEC(MID($B306,10+6*K$1,2)&MID($B306,13+6*K$1,2)) -> 18574 | L306: =HEX2DEC(MID($B306,10+6*L$1,2)&MID($B306,13+6*L$1,2))/10 -> 2220.8 | M306: =HEX2DEC(MID($B306,10+6*M$1,2)&MID($B306,13+6*M$1,2)) -> 0 | N306: =(HEX2DEC(MID($B306,10+6*N$1,2)&MID($B306,13+6*N$1,2))-65536)/10 -> -158.7 | O306: =HEX2DEC(MID($B306,10+6*O$1,2)&MID($B306,13+6*O$1,2)) -> 0 | P306: =HEX2DEC(MID($B306,10+6*P$1,2)&MID($B306,13+6*P$1,2)) -> 23448 | Q306: =HEX2DEC(MID($B306,10+6*Q$1,2)&MID($B306,13+6*Q$1,2)) -> 0 | R306: =HEX2DEC(MID($B306,10+6*R$1,2)&MID($B306,13+6*R$1,2)) -> 0 | S306: =VLOOKUP(J306,设备状态表!$D$3:$E$14,2,0) -> 向下运动到固定点监测
A307: [17:34:10.428]收← | B307: 01 03 20 57 BF 00 00 C1 FA 00 00 11 24 00 00 00 00 08 40 48 8E 56 60 00 00 F9 CD 00 00 5B 98 00 00 00 00 98 BF | C307: =HEX2DEC(MID(B307,10,2)&MID(B307,13,2)) -> 22463 | D307: =HEX2DEC(MID($B307,10+6*D$1,2)&MID($B307,13+6*D$1,2)) -> 0 | E307: =(HEX2DEC(MID($B307,10+6*E$1,2)&MID($B307,13+6*E$1,2))-65536)/100 -> -158.78 | F307: =HEX2DEC(MID($B307,10+6*F$1,2)&MID($B307,13+6*F$1,2)) -> 0 | G307: =HEX2DEC(MID($B307,10+6*G$1,2)&MID($B307,13+6*G$1,2))/10 -> 438.8 | H307: =HEX2DEC(MID($B307,10+6*H$1,2)&MID($B307,13+6*H$1,2)) -> 0 | I307: =HEX2DEC(MID($B307,10+6*I$1,2)&MID($B307,13+6*I$1,2)) -> 0 | J307: =HEX2DEC(MID($B307,10+6*J$1,2)&MID($B307,13+6*J$1,2)) -> 2112 | K307: =HEX2DEC(MID($B307,10+6*K$1,2)&MID($B307,13+6*K$1,2)) -> 18574 | L307: =HEX2DEC(MID($B307,10+6*L$1,2)&MID($B307,13+6*L$1,2))/10 -> 2211.2 | M307: =HEX2DEC(MID($B307,10+6*M$1,2)&MID($B307,13+6*M$1,2)) -> 0 | N307: =(HEX2DEC(MID($B307,10+6*N$1,2)&MID($B307,13+6*N$1,2))-65536)/10 -> -158.7 | O307: =HEX2DEC(MID($B307,10+6*O$1,2)&MID($B307,13+6*O$1,2)) -> 0 | P307: =HEX2DEC(MID($B307,10+6*P$1,2)&MID($B307,13+6*P$1,2)) -> 23448 | Q307: =HEX2DEC(MID($B307,10+6*Q$1,2)&MID($B307,13+6*Q$1,2)) -> 0 | R307: =HEX2DEC(MID($B307,10+6*R$1,2)&MID($B307,13+6*R$1,2)) -> 0 | S307: =VLOOKUP(J307,设备状态表!$D$3:$E$14,2,0) -> 向下运动到固定点监测
A308: [17:34:11.981]收← | B308: 01 03 20 57 8C 00 00 C1 FA 00 00 11 24 00 00 00 00 08 40 48 8E 56 80 00 00 F9 CD 00 00 5B 98 00 00 00 00 56 C4 | C308: =HEX2DEC(MID(B308,10,2)&MID(B308,13,2)) -> 22412 | D308: =HEX2DEC(MID($B308,10+6*D$1,2)&MID($B308,13+6*D$1,2)) -> 0 | E308: =(HEX2DEC(MID($B308,10+6*E$1,2)&MID($B308,13+6*E$1,2))-65536)/100 -> -158.78 | F308: =HEX2DEC(MID($B308,10+6*F$1,2)&MID($B308,13+6*F$1,2)) -> 0 | G308: =HEX2DEC(MID($B308,10+6*G$1,2)&MID($B308,13+6*G$1,2))/10 -> 438.8 | H308: =HEX2DEC(MID($B308,10+6*H$1,2)&MID($B308,13+6*H$1,2)) -> 0 | I308: =HEX2DEC(MID($B308,10+6*I$1,2)&MID($B308,13+6*I$1,2)) -> 0 | J308: =HEX2DEC(MID($B308,10+6*J$1,2)&MID($B308,13+6*J$1,2)) -> 2112 | K308: =HEX2DEC(MID($B308,10+6*K$1,2)&MID($B308,13+6*K$1,2)) -> 18574 | L308: =HEX2DEC(MID($B308,10+6*L$1,2)&MID($B308,13+6*L$1,2))/10 -> 2214.4 | M308: =HEX2DEC(MID($B308,10+6*M$1,2)&MID($B308,13+6*M$1,2)) -> 0 | N308: =(HEX2DEC(MID($B308,10+6*N$1,2)&MID($B308,13+6*N$1,2))-65536)/10 -> -158.7 | O308: =HEX2DEC(MID($B308,10+6*O$1,2)&MID($B308,13+6*O$1,2)) -> 0 | P308: =HEX2DEC(MID($B308,10+6*P$1,2)&MID($B308,13+6*P$1,2)) -> 23448 | Q308: =HEX2DEC(MID($B308,10+6*Q$1,2)&MID($B308,13+6*Q$1,2)) -> 0 | R308: =HEX2DEC(MID($B308,10+6*R$1,2)&MID($B308,13+6*R$1,2)) -> 0 | S308: =VLOOKUP(J308,设备状态表!$D$3:$E$14,2,0) -> 向下运动到固定点监测
A309: [17:34:15.059]收← | B309: 01 03 20 57 24 00 00 C1 FB 00 00 11 24 00 00 00 00 08 40 48 8E 56 C0 00 00 F9 CD 00 00 5B 98 00 00 00 00 D7 18 | C309: =HEX2DEC(MID(B309,10,2)&MID(B309,13,2)) -> 22308 | D309: =HEX2DEC(MID($B309,10+6*D$1,2)&MID($B309,13+6*D$1,2)) -> 0 | E309: =(HEX2DEC(MID($B309,10+6*E$1,2)&MID($B309,13+6*E$1,2))-65536)/100 -> -158.77 | F309: =HEX2DEC(MID($B309,10+6*F$1,2)&MID($B309,13+6*F$1,2)) -> 0 | G309: =HEX2DEC(MID($B309,10+6*G$1,2)&MID($B309,13+6*G$1,2))/10 -> 438.8 | H309: =HEX2DEC(MID($B309,10+6*H$1,2)&MID($B309,13+6*H$1,2)) -> 0 | I309: =HEX2DEC(MID($B309,10+6*I$1,2)&MID($B309,13+6*I$1,2)) -> 0 | J309: =HEX2DEC(MID($B309,10+6*J$1,2)&MID($B309,13+6*J$1,2)) -> 2112 | K309: =HEX2DEC(MID($B309,10+6*K$1,2)&MID($B309,13+6*K$1,2)) -> 18574 | L309: =HEX2DEC(MID($B309,10+6*L$1,2)&MID($B309,13+6*L$1,2))/10 -> 2220.8 | M309: =HEX2DEC(MID($B309,10+6*M$1,2)&MID($B309,13+6*M$1,2)) -> 0 | N309: =(HEX2DEC(MID($B309,10+6*N$1,2)&MID($B309,13+6*N$1,2))-65536)/10 -> -158.7 | O309: =HEX2DEC(MID($B309,10+6*O$1,2)&MID($B309,13+6*O$1,2)) -> 0 | P309: =HEX2DEC(MID($B309,10+6*P$1,2)&MID($B309,13+6*P$1,2)) -> 23448 | Q309: =HEX2DEC(MID($B309,10+6*Q$1,2)&MID($B309,13+6*Q$1,2)) -> 0 | R309: =HEX2DEC(MID($B309,10+6*R$1,2)&MID($B309,13+6*R$1,2)) -> 0 | S309: =VLOOKUP(J309,设备状态表!$D$3:$E$14,2,0) -> 向下运动到固定点监测
A310: [17:34:18.057]收← | B310: 01 03 20 56 BF 00 00 C1 FB 00 00 11 24 00 00 00 00 08 40 48 8E 56 40 00 00 F9 CD 00 00 5B 98 00 00 00 00 18 F1 | C310: =HEX2DEC(MID(B310,10,2)&MID(B310,13,2)) -> 22207 | D310: =HEX2DEC(MID($B310,10+6*D$1,2)&MID($B310,13+6*D$1,2)) -> 0 | E310: =(HEX2DEC(MID($B310,10+6*E$1,2)&MID($B310,13+6*E$1,2))-65536)/100 -> -158.77 | F310: =HEX2DEC(MID($B310,10+6*F$1,2)&MID($B310,13+6*F$1,2)) -> 0 | G310: =HEX2DEC(MID($B310,10+6*G$1,2)&MID($B310,13+6*G$1,2))/10 -> 438.8 | H310: =HEX2DEC(MID($B310,10+6*H$1,2)&MID($B310,13+6*H$1,2)) -> 0 | I310: =HEX2DEC(MID($B310,10+6*I$1,2)&MID($B310,13+6*I$1,2)) -> 0 | J310: =HEX2DEC(MID($B310,10+6*J$1,2)&MID($B310,13+6*J$1,2)) -> 2112 | K310: =HEX2DEC(MID($B310,10+6*K$1,2)&MID($B310,13+6*K$1,2)) -> 18574 | L310: =HEX2DEC(MID($B310,10+6*L$1,2)&MID($B310,13+6*L$1,2))/10 -> 2208 | M310: =HEX2DEC(MID($B310,10+6*M$1,2)&MID($B310,13+6*M$1,2)) -> 0 | N310: =(HEX2DEC(MID($B310,10+6*N$1,2)&MID($B310,13+6*N$1,2))-65536)/10 -> -158.7 | O310: =HEX2DEC(MID($B310,10+6*O$1,2)&MID($B310,13+6*O$1,2)) -> 0 | P310: =HEX2DEC(MID($B310,10+6*P$1,2)&MID($B310,13+6*P$1,2)) -> 23448 | Q310: =HEX2DEC(MID($B310,10+6*Q$1,2)&MID($B310,13+6*Q$1,2)) -> 0 | R310: =HEX2DEC(MID($B310,10+6*R$1,2)&MID($B310,13+6*R$1,2)) -> 0 | S310: =VLOOKUP(J310,设备状态表!$D$3:$E$14,2,0) -> 向下运动到固定点监测
A311: [17:34:20.991]收← | B311: 01 03 20 56 5C 00 00 C1 FA 00 00 11 24 00 00 00 00 08 40 48 8E 55 E0 00 00 F9 CD 00 00 5B 98 00 00 00 00 D4 6E | C311: =HEX2DEC(MID(B311,10,2)&MID(B311,13,2)) -> 22108 | D311: =HEX2DEC(MID($B311,10+6*D$1,2)&MID($B311,13+6*D$1,2)) -> 0 | E311: =(HEX2DEC(MID($B311,10+6*E$1,2)&MID($B311,13+6*E$1,2))-65536)/100 -> -158.78 | F311: =HEX2DEC(MID($B311,10+6*F$1,2)&MID($B311,13+6*F$1,2)) -> 0 | G311: =HEX2DEC(MID($B311,10+6*G$1,2)&MID($B311,13+6*G$1,2))/10 -> 438.8 | H311: =HEX2DEC(MID($B311,10+6*H$1,2)&MID($B311,13+6*H$1,2)) -> 0 | I311: =HEX2DEC(MID($B311,10+6*I$1,2)&MID($B311,13+6*I$1,2)) -> 0 | J311: =HEX2DEC(MID($B311,10+6*J$1,2)&MID($B311,13+6*J$1,2)) -> 2112 | K311: =HEX2DEC(MID($B311,10+6*K$1,2)&MID($B311,13+6*K$1,2)) -> 18574 | L311: =HEX2DEC(MID($B311,10+6*L$1,2)&MID($B311,13+6*L$1,2))/10 -> 2198.4 | M311: =HEX2DEC(MID($B311,10+6*M$1,2)&MID($B311,13+6*M$1,2)) -> 0 | N311: =(HEX2DEC(MID($B311,10+6*N$1,2)&MID($B311,13+6*N$1,2))-65536)/10 -> -158.7 | O311: =HEX2DEC(MID($B311,10+6*O$1,2)&MID($B311,13+6*O$1,2)) -> 0 | P311: =HEX2DEC(MID($B311,10+6*P$1,2)&MID($B311,13+6*P$1,2)) -> 23448 | Q311: =HEX2DEC(MID($B311,10+6*Q$1,2)&MID($B311,13+6*Q$1,2)) -> 0 | R311: =HEX2DEC(MID($B311,10+6*R$1,2)&MID($B311,13+6*R$1,2)) -> 0 | S311: =VLOOKUP(J311,设备状态表!$D$3:$E$14,2,0) -> 向下运动到固定点监测
A312: [17:34:23.969]收← | B312: 01 03 20 55 FA 00 00 C1 FA 00 00 11 24 00 00 00 00 08 40 48 8E 56 C0 00 00 F9 CD 00 00 5B 98 00 00 00 00 C8 E0 | C312: =HEX2DEC(MID(B312,10,2)&MID(B312,13,2)) -> 22010 | D312: =HEX2DEC(MID($B312,10+6*D$1,2)&MID($B312,13+6*D$1,2)) -> 0 | E312: =(HEX2DEC(MID($B312,10+6*E$1,2)&MID($B312,13+6*E$1,2))-65536)/100 -> -158.78 | F312: =HEX2DEC(MID($B312,10+6*F$1,2)&MID($B312,13+6*F$1,2)) -> 0 | G312: =HEX2DEC(MID($B312,10+6*G$1,2)&MID($B312,13+6*G$1,2))/10 -> 438.8 | H312: =HEX2DEC(MID($B312,10+6*H$1,2)&MID($B312,13+6*H$1,2)) -> 0 | I312: =HEX2DEC(MID($B312,10+6*I$1,2)&MID($B312,13+6*I$1,2)) -> 0 | J312: =HEX2DEC(MID($B312,10+6*J$1,2)&MID($B312,13+6*J$1,2)) -> 2112 | K312: =HEX2DEC(MID($B312,10+6*K$1,2)&MID($B312,13+6*K$1,2)) -> 18574 | L312: =HEX2DEC(MID($B312,10+6*L$1,2)&MID($B312,13+6*L$1,2))/10 -> 2220.8 | M312: =HEX2DEC(MID($B312,10+6*M$1,2)&MID($B312,13+6*M$1,2)) -> 0 | N312: =(HEX2DEC(MID($B312,10+6*N$1,2)&MID($B312,13+6*N$1,2))-65536)/10 -> -158.7 | O312: =HEX2DEC(MID($B312,10+6*O$1,2)&MID($B312,13+6*O$1,2)) -> 0 | P312: =HEX2DEC(MID($B312,10+6*P$1,2)&MID($B312,13+6*P$1,2)) -> 23448 | Q312: =HEX2DEC(MID($B312,10+6*Q$1,2)&MID($B312,13+6*Q$1,2)) -> 0 | R312: =HEX2DEC(MID($B312,10+6*R$1,2)&MID($B312,13+6*R$1,2)) -> 0 | S312: =VLOOKUP(J312,设备状态表!$D$3:$E$14,2,0) -> 向下运动到固定点监测
... A436: [17:41:26.918]收← | B436: 01 03 20 1E 8E 00 00 C1 FC 00 00 11 22 00 00 00 00 08 40 48 8E 51 E0 00 00 F9 CD 00 00 5B 98 00 00 00 00 7A 2A | C436: =HEX2DEC(MID(B436,10,2)&MID(B436,13,2)) -> 7822 | D436: =HEX2DEC(MID($B436,10+6*D$1,2)&MID($B436,13+6*D$1,2)) -> 0 | E436: =(HEX2DEC(MID($B436,10+6*E$1,2)&MID($B436,13+6*E$1,2))-65536)/100 -> -158.76 | F436: =HEX2DEC(MID($B436,10+6*F$1,2)&MID($B436,13+6*F$1,2)) -> 0 | G436: =HEX2DEC(MID($B436,10+6*G$1,2)&MID($B436,13+6*G$1,2))/10 -> 438.6 | H436: =HEX2DEC(MID($B436,10+6*H$1,2)&MID($B436,13+6*H$1,2)) -> 0 | I436: =HEX2DEC(MID($B436,10+6*I$1,2)&MID($B436,13+6*I$1,2)) -> 0 | J436: =HEX2DEC(MID($B436,10+6*J$1,2)&MID($B436,13+6*J$1,2)) -> 2112 | K436: =HEX2DEC(MID($B436,10+6*K$1,2)&MID($B436,13+6*K$1,2)) -> 18574 | L436: =HEX2DEC(MID($B436,10+6*L$1,2)&MID($B436,13+6*L$1,2))/10 -> 2096 | M436: =HEX2DEC(MID($B436,10+6*M$1,2)&MID($B436,13+6*M$1,2)) -> 0 | N436: =(HEX2DEC(MID($B436,10+6*N$1,2)&MID($B436,13+6*N$1,2))-65536)/10 -> -158.7 | O436: =HEX2DEC(MID($B436,10+6*O$1,2)&MID($B436,13+6*O$1,2)) -> 0 | P436: =HEX2DEC(MID($B436,10+6*P$1,2)&MID($B436,13+6*P$1,2)) -> 23448 | Q436: =HEX2DEC(MID($B436,10+6*Q$1,2)&MID($B436,13+6*Q$1,2)) -> 0 | R436: =HEX2DEC(MID($B436,10+6*R$1,2)&MID($B436,13+6*R$1,2)) -> 0 | S436: =VLOOKUP(J436,设备状态表!$D$3:$E$14,2,0) -> 向下运动到固定点监测

Sheet 提零点原始数据
A2: [17:46:44.168]收← | B2: 01 03 20 01 F1 00 00 C1 FD 00 00 11 22 00 00 00 00 00 44 48 8E 50 A0 00 00 F9 CD 00 00 5B 98 00 00 00 00 C5 D6 | C2: =MID(B2,1,9) -> 01 03 20
A3: [17:46:44.311]收← | B3: 04 03 00 C8 00 11 04 6D | C3: =MID(B3,1,9) -> 04 03 00
A4: [17:46:44.651]收← | B4: 04 03 22 46 B8 04 00 3F 80 00 00 3F 80 00 00 3F 80 00 00 00 00 00 00 00 00 10 06 00 00 00 00 00 00 00 00 00 00 33 61 | C4: =MID(B4,1,9) -> 04 03 22
A5: [17:46:44.792]收← | B5: 03 03 00 1E 00 05 E4 2D | C5: =MID(B5,1,9) -> 03 03 00
A6: [17:46:44.888]收← | B6: 03 03 0A 31 37 30 39 31 38 30 38 32 31 55 75 | C6: =MID(B6,1,9) -> 03 03 0A
A7: [17:46:45.030]收← | B7: 02 03 00 C8 00 11 04 0B | C7: =MID(B7,1,9) -> 02 03 00
A8: [17:46:45.237]收← | B8: 02 03 22 46 B7 EC 00 C4 C7 20 00 41 30 | C8: =MID(B8,1,9) -> 02 03 22
A9: [17:46:45.300]收← | B9: 00 00 C4 C4 80 00 00 00 00 00 00 00 | C9: =MID(B9,1,9) -> 00 00 C4
A10: [17:46:45.364]收← | B10: 10 00 00 00 00 00 00 00 00 00 00 00 AE DC | C10: =MID(B10,1,9) -> 10 00 00
A11: [17:46:45.480]收← | B11: 01 03 00 00 00 10 44 06 | C11: =MID(B11,1,9) -> 01 03 00
A12: [17:46:45.663]收← | B12: 01 03 20 01 F1 00 00 C1 FD 00 00 11 21 00 00 00 00 00 44 48 8E 4F A0 00 00 F9 CD 00 00 5B 98 00 00 00 00 8F EC | C12: =MID(B12,1,9) -> 01 03 20
A13: [17:46:47.302]收← | B13: 04 03 00 C8 00 11 04 6D | C13: =MID(B13,1,9) -> 04 03 00
... A80: [17:47:09.008]收← | B80: 02 03 00 C8 00 11 04 0B | C80: =MID(B80,1,9) -> 02 03 00
A81: [17:47:09.198]收← | B81: 2 | C81: =MID(B81,1,9) -> 2
A82: [17:47:09.342]收← | B82: 03 22 46 B7 EC 00 C4 C7 00 00 41 30 00 00 C4 C4 80 00 00 00 00 00 00 00 10 00 00 00 00 00 00 00 00 00 00 00 F1 9C | C82: =MID(B82,1,9) -> 03 22 46
A83: [17:47:09.482]收← | B83: 01 03 00 00 00 10 44 06 | C83: =MID(B83,1,9) -> 01 03 00
A84: [17:47:09.672]收← | B84: 01 03 20 03 25 00 00 C1 FE 00 00 11 22 00 00 00 00 08 60 48 8E 50 A0 00 00 F9 CD 00 00 5B 98 00 00 00 00 5C 07 | C84: =MID(B84,1,9) -> 01 03 20
A85: [17:47:11.315]收← | B85: 04 03 00 C8 00 11 04 6D | C85: =MID(B85,1,9) -> 04 03 00
A86: [17:47:11.745]收← | B86: 04 03 22 46 B8 04 00 3F 80 00 00 3F 80 00 00 3F 80 00 00 00 00 00 00 00 00 10 06 00 00 00 00 00 00 00 00 00 00 33 61 | C86: =MID(B86,1,9) -> 04 03 22
A87: [17:47:11.894]收← | B87: 04 03 01 2C 00 21 45 B2 | C87: =MID(B87,1,9) -> 04 03 01
A88: [17:47:12.321]收← | B88: 04 03 42 FF FF 3F 80 00 00 3F 80 00 00 3F 80 00 00 3F 80 00 00 3F 80 00 00 3F 80 00 00 3F 80 00 | C88: =MID(B88,1,9) -> 04 03 42
A89: [17:47:12.482]收← | B89: 00 3F 80 00 00 3F 80 00 00 3F 80 00 00 3F 80 00 00 3F 80 00 00 3F 80 00 00 3F 80 00 00 3F 80 00 00 3F 80 00 00 3F 80 | C89: =MID(B89,1,9) -> 00 3F 80
A90: [17:47:12.630]收← | B90: 04 03 01 54 00 21 C5 AB | C90: =MID(B90,1,9) -> 04 03 01
A91: [17:47:13.007]收← | B91: 04 03 42 FF FF 3F 80 00 00 3F 80 00 00 3F 80 00 00 3F 80 00 00 3F 80 00 00 3F 80 00 00 3F 80 00 | C91: =MID(B91,1,9) -> 04 03 42
A92: [17:47:13.164]收← | B92: 00 3F 80 00 00 3F 80 00 00 3F 80 00 00 3F 80 00 00 3F 80 00 00 3F 80 00 00 3F 80 00 00 3F 80 00 00 3F 80 00 00 3F 80 | C92: =MID(B92,1,9) -> 00 3F 80
A93: [17:47:13.316]收← | B93: 04 03 01 75 00 21 95 A1 | C93: =MID(B93,1,9) -> 04 03 01
... A859: [17:50:36.095]收← | B859: 02 03 00 C8 00 11 04 0B | C859: =MID(B859,1,9) -> 02 03 00
A860: [17:50:36.241]收← | B860: 2 | C860: =MID(B860,1,9) -> 2
A861: [17:50:36.304]收← | B861: 03 22 46 B7 EC 00 C4 C7 00 00 41 30 00 | C861: =MID(B861,1,9) -> 03 22 46
A862: [17:50:36.369]收← | B862: 00 C4 C4 60 00 00 00 00 00 00 00 10 00 00 00 00 00 00 00 00 00 00 00 67 EA | C862: =MID(B862,1,9) -> 00 C4 C4
A863: [17:50:36.527]收← | B863: 01 03 00 00 00 10 44 06 | C863: =MID(B863,1,9) -> 01 03 00
A864: [17:50:36.722]收← | B864: 01 03 20 1E C3 00 00 C1 FD 00 00 11 22 00 00 00 00 08 60 48 8E 51 60 00 00 F9 CD 00 00 5B 98 00 00 00 00 32 81 | C864: =MID(B864,1,9) -> 01 03 20
A865: [17:50:38.390]收← | B865: 04 03 00 C8 00 11 04 6D | C865: =MID(B865,1,9) -> 04 03 00
A866: [17:50:38.811]收← | B866: 04 03 22 46 B8 04 00 3F 80 00 00 3F 80 00 00 3F 80 00 00 00 00 00 00 00 00 10 06 00 00 00 00 00 00 00 00 00 00 33 61 | C866: =MID(B866,1,9) -> 04 03 22
A867: [17:50:38.949]收← | B867: 03 03 00 1E 00 05 E4 2D | C867: =MID(B867,1,9) -> 03 03 00
A868: [17:50:39.028]收← | B868: 03 03 0A 31 37 30 39 31 38 30 38 32 31 55 75 | C868: =MID(B868,1,9) -> 03 03 0A
A869: [17:50:39.187]收← | B869: 02 03 00 C8 00 11 04 0B | C869: =MID(B869,1,9) -> 02 03 00
A870: [17:50:39.471]收← | B870: 02 03 22 46 B7 EC 00 C4 C7 00 00 41 30 00 00 C4 C4 60 00 00 00 00 00 00 00 | C870: =MID(B870,1,9) -> 02 03 22
A871: [17:50:39.582]收← | B871: 10 00 00 00 00 00 00 00 00 00 00 00 67 EA | C871: =MID(B871,1,9) -> 10 00 00
A872: [17:50:39.709]收← | B872: 01 03 00 00 00 10 44 06 | C872: =MID(B872,1,9) -> 01 03 00
...

Sheet 提零点
C1: 0 | D1: 1 | E1: 2 | F1: 3 | G1: 4 | H1: 5 | I1: 6 | J1: 7 | K1: 8 | L1: 9 | M1: 10 | N1: 11 | O1: 12 | P1: 13 | Q1: 14 | R1: 15
A2: [17:46:44.168]收← | B2: 01 03 20 01 F1 00 00 C1 FD 00 00 11 22 00 00 00 00 00 44 48 8E 50 A0 00 00 F9 CD 00 00 5B 98 00 00 00 00 C5 D6 | C2: 浮子位置 | D2: 浮子状态 | E2: 温度 | F2: 温度状态 | G2: 密度值 | H2: 密度状态 | I2: 下发指令 | J2: 设备工作状态 | K2: （幅值）未知 | L2: 频率值 | M2: 未知状态位 | N2: 温度 | O2: 温度状态 | P2: 液位值 | Q2: 液位状态 | R2: 位置 | S2: 状态解析
A3: [17:46:45.663]收← | B3: 01 03 20 01 F1 00 00 C1 FD 00 00 11 21 00 00 00 00 00 44 48 8E 4F A0 00 00 F9 CD 00 00 5B 98 00 00 00 00 8F EC | C3: =HEX2DEC(MID($B3,10+6*C1,2)&MID($B3,13+6*C1,2)) -> 497 | D3: =HEX2DEC(MID($B3,10+6*D$1,2)&MID($B3,13+6*D$1,2)) -> 0 | E3: =(HEX2DEC(MID($B3,10+6*E$1,2)&MID($B3,13+6*E$1,2))-65536)/100 -> -158.75 | F3: =HEX2DEC(MID($B3,10+6*F$1,2)&MID($B3,13+6*F$1,2)) -> 0 | G3: =HEX2DEC(MID($B3,10+6*G$1,2)&MID($B3,13+6*G$1,2))/10 -> 438.5 | H3: =HEX2DEC(MID($B3,10+6*H$1,2)&MID($B3,13+6*H$1,2)) -> 0 | I3: =HEX2DEC(MID($B3,10+6*I$1,2)&MID($B3,13+6*I$1,2)) -> 0 | J3: =HEX2DEC(MID($B3,10+6*J$1,2)&MID($B3,13+6*J$1,2)) -> 68 | K3: =HEX2DEC(MID($B3,10+6*K$1,2)&MID($B3,13+6*K$1,2)) -> 18574 | L3: =HEX2DEC(MID($B3,10+6*L$1,2)&MID($B3,13+6*L$1,2))/10 -> 2038.4 | M3: =HEX2DEC(MID($B3,10+6*M$1,2)&MID($B3,13+6*M$1,2)) -> 0 | N3: =(HEX2DEC(MID($B3,10+6*N$1,2)&MID($B3,13+6*N$1,2))-65536)/10 -> -158.7 | O3: =HEX2DEC(MID($B3,10+6*O$1,2)&MID($B3,13+6*O$1,2)) -> 0 | P3: =HEX2DEC(MID($B3,10+6*P$1,2)&MID($B3,13+6*P$1,2)) -> 23448 | Q3: =HEX2DEC(MID($B3,10+6*Q$1,2)&MID($B3,13+6*Q$1,2)) -> 0 | R3: =HEX2DEC(MID($B3,10+6*R$1,2)&MID($B3,13+6*R$1,2)) -> 0 | S3: =VLOOKUP(J3,设备状态表!$D$3:$E$14,2,0) -> 固定点监测中
A4: [17:46:48.799]收← | B4: 01 03 20 01 F1 00 00 C1 FD 00 00 11 21 00 00 00 00 00 44 48 8E 51 60 00 00 F9 CD 00 00 5B 98 00 00 00 00 90 F3 | C4: =HEX2DEC(MID(B4,10,2)&MID(B4,13,2)) -> 497 | D4: =HEX2DEC(MID($B4,10+6*D$1,2)&MID($B4,13+6*D$1,2)) -> 0 | E4: =(HEX2DEC(MID($B4,10+6*E$1,2)&MID($B4,13+6*E$1,2))-65536)/100 -> -158.75 | F4: =HEX2DEC(MID($B4,10+6*F$1,2)&MID($B4,13+6*F$1,2)) -> 0 | G4: =HEX2DEC(MID($B4,10+6*G$1,2)&MID($B4,13+6*G$1,2))/10 -> 438.5 | H4: =HEX2DEC(MID($B4,10+6*H$1,2)&MID($B4,13+6*H$1,2)) -> 0 | I4: =HEX2DEC(MID($B4,10+6*I$1,2)&MID($B4,13+6*I$1,2)) -> 0 | J4: =HEX2DEC(MID($B4,10+6*J$1,2)&MID($B4,13+6*J$1,2)) -> 68 | K4: =HEX2DEC(MID($B4,10+6*K$1,2)&MID($B4,13+6*K$1,2)) -> 18574 | L4: =HEX2DEC(MID($B4,10+6*L$1,2)&MID($B4,13+6*L$1,2))/10 -> 2083.2 | M4: =HEX2DEC(MID($B4,10+6*M$1,2)&MID($B4,13+6*M$1,2)) -> 0 | N4: =(HEX2DEC(MID($B4,10+6*N$1,2)&MID($B4,13+6*N$1,2))-65536)/10 -> -158.7 | O4: =HEX2DEC(MID($B4,10+6*O$1,2)&MID($B4,13+6*O$1,2)) -> 0 | P4: =HEX2DEC(MID($B4,10+6*P$1,2)&MID($B4,13+6*P$1,2)) -> 23448 | Q4: =HEX2DEC(MID($B4,10+6*Q$1,2)&MID($B4,13+6*Q$1,2)) -> 0 | R4: =HEX2DEC(MID($B4,10+6*R$1,2)&MID($B4,13+6*R$1,2)) -> 0 | S4: =VLOOKUP(J4,设备状态表!$D$3:$E$14,2,0) -> 固定点监测中
A5: [17:46:51.794]收← | B5: 01 03 20 01 F1 00 00 C1 FC 00 00 11 21 00 00 00 00 00 44 48 8E 50 80 00 00 F9 CD 00 00 5B 98 00 00 00 00 10 D1 | C5: =HEX2DEC(MID(B5,10,2)&MID(B5,13,2)) -> 497 | D5: =HEX2DEC(MID($B5,10+6*D$1,2)&MID($B5,13+6*D$1,2)) -> 0 | E5: =(HEX2DEC(MID($B5,10+6*E$1,2)&MID($B5,13+6*E$1,2))-65536)/100 -> -158.76 | F5: =HEX2DEC(MID($B5,10+6*F$1,2)&MID($B5,13+6*F$1,2)) -> 0 | G5: =HEX2DEC(MID($B5,10+6*G$1,2)&MID($B5,13+6*G$1,2))/10 -> 438.5 | H5: =HEX2DEC(MID($B5,10+6*H$1,2)&MID($B5,13+6*H$1,2)) -> 0 | I5: =HEX2DEC(MID($B5,10+6*I$1,2)&MID($B5,13+6*I$1,2)) -> 0 | J5: =HEX2DEC(MID($B5,10+6*J$1,2)&MID($B5,13+6*J$1,2)) -> 68 | K5: =HEX2DEC(MID($B5,10+6*K$1,2)&MID($B5,13+6*K$1,2)) -> 18574 | L5: =HEX2DEC(MID($B5,10+6*L$1,2)&MID($B5,13+6*L$1,2))/10 -> 2060.8 | M5: =HEX2DEC(MID($B5,10+6*M$1,2)&MID($B5,13+6*M$1,2)) -> 0 | N5: =(HEX2DEC(MID($B5,10+6*N$1,2)&MID($B5,13+6*N$1,2))-65536)/10 -> -158.7 | O5: =HEX2DEC(MID($B5,10+6*O$1,2)&MID($B5,13+6*O$1,2)) -> 0 | P5: =HEX2DEC(MID($B5,10+6*P$1,2)&MID($B5,13+6*P$1,2)) -> 23448 | Q5: =HEX2DEC(MID($B5,10+6*Q$1,2)&MID($B5,13+6*Q$1,2)) -> 0 | R5: =HEX2DEC(MID($B5,10+6*R$1,2)&MID($B5,13+6*R$1,2)) -> 0 | S5: =VLOOKUP(J5,设备状态表!$D$3:$E$14,2,0) -> 固定点监测中
A6: [17:46:54.922]收← | B6: 01 03 20 01 F1 00 00 C1 FC 00 00 11 21 00 00 00 00 00 44 48 8E 50 A0 00 00 F9 CD 00 00 5B 98 00 00 00 00 6F B1 | C6: =HEX2DEC(MID(B6,10,2)&MID(B6,13,2)) -> 497 | D6: =HEX2DEC(MID($B6,10+6*D$1,2)&MID($B6,13+6*D$1,2)) -> 0 | E6: =(HEX2DEC(MID($B6,10+6*E$1,2)&MID($B6,13+6*E$1,2))-65536)/100 -> -158.76 | F6: =HEX2DEC(MID($B6,10+6*F$1,2)&MID($B6,13+6*F$1,2)) -> 0 | G6: =HEX2DEC(MID($B6,10+6*G$1,2)&MID($B6,13+6*G$1,2))/10 -> 438.5 | H6: =HEX2DEC(MID($B6,10+6*H$1,2)&MID($B6,13+6*H$1,2)) -> 0 | I6: =HEX2DEC(MID($B6,10+6*I$1,2)&MID($B6,13+6*I$1,2)) -> 0 | J6: =HEX2DEC(MID($B6,10+6*J$1,2)&MID($B6,13+6*J$1,2)) -> 68 | K6: =HEX2DEC(MID($B6,10+6*K$1,2)&MID($B6,13+6*K$1,2)) -> 18574 | L6: =HEX2DEC(MID($B6,10+6*L$1,2)&MID($B6,13+6*L$1,2))/10 -> 2064 | M6: =HEX2DEC(MID($B6,10+6*M$1,2)&MID($B6,13+6*M$1,2)) -> 0 | N6: =(HEX2DEC(MID($B6,10+6*N$1,2)&MID($B6,13+6*N$1,2))-65536)/10 -> -158.7 | O6: =HEX2DEC(MID($B6,10+6*O$1,2)&MID($B6,13+6*O$1,2)) -> 0 | P6: =HEX2DEC(MID($B6,10+6*P$1,2)&MID($B6,13+6*P$1,2)) -> 23448 | Q6: =HEX2DEC(MID($B6,10+6*Q$1,2)&MID($B6,13+6*Q$1,2)) -> 0 | R6: =HEX2DEC(MID($B6,10+6*R$1,2)&MID($B6,13+6*R$1,2)) -> 0 | S6: =VLOOKUP(J6,设备状态表!$D$3:$E$14,2,0) -> 固定点监测中
A7: [17:46:57.722]收← | B7: 01 03 20 01 F7 00 00 C1 FE 00 00 11 22 00 00 00 00 08 64 48 8E 50 80 00 00 F9 CD 00 00 5B 98 00 00 00 00 40 DA | C7: =HEX2DEC(MID(B7,10,2)&MID(B7,13,2)) -> 503 | D7: =HEX2DEC(MID($B7,10+6*D$1,2)&MID($B7,13+6*D$1,2)) -> 0 | E7: =(HEX2DEC(MID($B7,10+6*E$1,2)&MID($B7,13+6*E$1,2))-65536)/100 -> -158.74 | F7: =HEX2DEC(MID($B7,10+6*F$1,2)&MID($B7,13+6*F$1,2)) -> 0 | G7: =HEX2DEC(MID($B7,10+6*G$1,2)&MID($B7,13+6*G$1,2))/10 -> 438.6 | H7: =HEX2DEC(MID($B7,10+6*H$1,2)&MID($B7,13+6*H$1,2)) -> 0 | I7: =HEX2DEC(MID($B7,10+6*I$1,2)&MID($B7,13+6*I$1,2)) -> 0 | J7: =HEX2DEC(MID($B7,10+6*J$1,2)&MID($B7,13+6*J$1,2)) -> 2148 | K7: =HEX2DEC(MID($B7,10+6*K$1,2)&MID($B7,13+6*K$1,2)) -> 18574 | L7: =HEX2DEC(MID($B7,10+6*L$1,2)&MID($B7,13+6*L$1,2))/10 -> 2060.8 | M7: =HEX2DEC(MID($B7,10+6*M$1,2)&MID($B7,13+6*M$1,2)) -> 0 | N7: =(HEX2DEC(MID($B7,10+6*N$1,2)&MID($B7,13+6*N$1,2))-65536)/10 -> -158.7 | O7: =HEX2DEC(MID($B7,10+6*O$1,2)&MID($B7,13+6*O$1,2)) -> 0 | P7: =HEX2DEC(MID($B7,10+6*P$1,2)&MID($B7,13+6*P$1,2)) -> 23448 | Q7: =HEX2DEC(MID($B7,10+6*Q$1,2)&MID($B7,13+6*Q$1,2)) -> 0 | R7: =HEX2DEC(MID($B7,10+6*R$1,2)&MID($B7,13+6*R$1,2)) -> 0 | S7: =VLOOKUP(J7,设备状态表!$D$3:$E$14,2,0) -> 接收到提浮子指令
A8: [17:47:00.619]收← | B8: 01 03 20 02 19 00 00 C1 FD 00 00 11 21 00 00 00 00 08 60 48 8E 50 40 00 00 F9 CD 00 00 5B 98 00 00 00 00 B6 F5 | C8: =HEX2DEC(MID(B8,10,2)&MID(B8,13,2)) -> 537 | D8: =HEX2DEC(MID($B8,10+6*D$1,2)&MID($B8,13+6*D$1,2)) -> 0 | E8: =(HEX2DEC(MID($B8,10+6*E$1,2)&MID($B8,13+6*E$1,2))-65536)/100 -> -158.75 | F8: =HEX2DEC(MID($B8,10+6*F$1,2)&MID($B8,13+6*F$1,2)) -> 0 | G8: =HEX2DEC(MID($B8,10+6*G$1,2)&MID($B8,13+6*G$1,2))/10 -> 438.5 | H8: =HEX2DEC(MID($B8,10+6*H$1,2)&MID($B8,13+6*H$1,2)) -> 0 | I8: =HEX2DEC(MID($B8,10+6*I$1,2)&MID($B8,13+6*I$1,2)) -> 0 | J8: =HEX2DEC(MID($B8,10+6*J$1,2)&MID($B8,13+6*J$1,2)) -> 2144 | K8: =HEX2DEC(MID($B8,10+6*K$1,2)&MID($B8,13+6*K$1,2)) -> 18574 | L8: =HEX2DEC(MID($B8,10+6*L$1,2)&MID($B8,13+6*L$1,2))/10 -> 2054.4 | M8: =HEX2DEC(MID($B8,10+6*M$1,2)&MID($B8,13+6*M$1,2)) -> 0 | N8: =(HEX2DEC(MID($B8,10+6*N$1,2)&MID($B8,13+6*N$1,2))-65536)/10 -> -158.7 | O8: =HEX2DEC(MID($B8,10+6*O$1,2)&MID($B8,13+6*O$1,2)) -> 0 | P8: =HEX2DEC(MID($B8,10+6*P$1,2)&MID($B8,13+6*P$1,2)) -> 23448 | Q8: =HEX2DEC(MID($B8,10+6*Q$1,2)&MID($B8,13+6*Q$1,2)) -> 0 | R8: =HEX2DEC(MID($B8,10+6*R$1,2)&MID($B8,13+6*R$1,2)) -> 0 | S8: =VLOOKUP(J8,设备状态表!$D$3:$E$14,2,0) -> 提浮子，向上运行，液体
A9: [17:47:03.801]收← | B9: 01 03 20 02 69 00 00 C1 FE 00 00 11 22 00 00 00 00 08 60 48 8E 50 20 00 00 F9 CD 00 00 5B 98 00 00 00 00 63 88 | C9: =HEX2DEC(MID(B9,10,2)&MID(B9,13,2)) -> 617 | D9: =HEX2DEC(MID($B9,10+6*D$1,2)&MID($B9,13+6*D$1,2)) -> 0 | E9: =(HEX2DEC(MID($B9,10+6*E$1,2)&MID($B9,13+6*E$1,2))-65536)/100 -> -158.74 | F9: =HEX2DEC(MID($B9,10+6*F$1,2)&MID($B9,13+6*F$1,2)) -> 0 | G9: =HEX2DEC(MID($B9,10+6*G$1,2)&MID($B9,13+6*G$1,2))/10 -> 438.6 | H9: =HEX2DEC(MID($B9,10+6*H$1,2)&MID($B9,13+6*H$1,2)) -> 0 | I9: =HEX2DEC(MID($B9,10+6*I$1,2)&MID($B9,13+6*I$1,2)) -> 0 | J9: =HEX2DEC(MID($B9,10+6*J$1,2)&MID($B9,13+6*J$1,2)) -> 2144 | K9: =HEX2DEC(MID($B9,10+6*K$1,2)&MID($B9,13+6*K$1,2)) -> 18574 | L9: =HEX2DEC(MID($B9,10+6*L$1,2)&MID($B9,13+6*L$1,2))/10 -> 2051.2 | M9: =HEX2DEC(MID($B9,10+6*M$1,2)&MID($B9,13+6*M$1,2)) -> 0 | N9: =(HEX2DEC(MID($B9,10+6*N$1,2)&MID($B9,13+6*N$1,2))-65536)/10 -> -158.7 | O9: =HEX2DEC(MID($B9,10+6*O$1,2)&MID($B9,13+6*O$1,2)) -> 0 | P9: =HEX2DEC(MID($B9,10+6*P$1,2)&MID($B9,13+6*P$1,2)) -> 23448 | Q9: =HEX2DEC(MID($B9,10+6*Q$1,2)&MID($B9,13+6*Q$1,2)) -> 0 | R9: =HEX2DEC(MID($B9,10+6*R$1,2)&MID($B9,13+6*R$1,2)) -> 0 | S9: =VLOOKUP(J9,设备状态表!$D$3:$E$14,2,0) -> 提浮子，向上运行，液体
A10: [17:47:06.777]收← | B10: 01 03 20 02 C7 00 00 C1 FE 00 00 11 22 00 00 00 00 08 60 48 8E 50 80 00 00 F9 CD 00 00 5B 98 00 00 00 00 02 B4 | C10: =HEX2DEC(MID(B10,10,2)&MID(B10,13,2)) -> 711 | D10: =HEX2DEC(MID($B10,10+6*D$1,2)&MID($B10,13+6*D$1,2)) -> 0 | E10: =(HEX2DEC(MID($B10,10+6*E$1,2)&MID($B10,13+6*E$1,2))-65536)/100 -> -158.74 | F10: =HEX2DEC(MID($B10,10+6*F$1,2)&MID($B10,13+6*F$1,2)) -> 0 | G10: =HEX2DEC(MID($B10,10+6*G$1,2)&MID($B10,13+6*G$1,2))/10 -> 438.6 | H10: =HEX2DEC(MID($B10,10+6*H$1,2)&MID($B10,13+6*H$1,2)) -> 0 | I10: =HEX2DEC(MID($B10,10+6*I$1,2)&MID($B10,13+6*I$1,2)) -> 0 | J10: =HEX2DEC(MID($B10,10+6*J$1,2)&MID($B10,13+6*J$1,2)) -> 2144 | K10: =HEX2DEC(MID($B10,10+6*K$1,2)&MID($B10,13+6*K$1,2)) -> 18574 | L10: =HEX2DEC(MID($B10,10+6*L$1,2)&MID($B10,13+6*L$1,2))/10 -> 2060.8 | M10: =HEX2DEC(MID($B10,10+6*M$1,2)&MID($B10,13+6*M$1,2)) -> 0 | N10: =(HEX2DEC(MID($B10,10+6*N$1,2)&MID($B10,13+6*N$1,2))-65536)/10 -> -158.7 | O10: =HEX2DEC(MID($B10,10+6*O$1,2)&MID($B10,13+6*O$1,2)) -> 0 | P10: =HEX2DEC(MID($B10,10+6*P$1,2)&MID($B10,13+6*P$1,2)) -> 23448 | Q10: =HEX2DEC(MID($B10,10+6*Q$1,2)&MID($B10,13+6*Q$1,2)) -> 0 | R10: =HEX2DEC(MID($B10,10+6*R$1,2)&MID($B10,13+6*R$1,2)) -> 0 | S10: =VLOOKUP(J10,设备状态表!$D$3:$E$14,2,0) -> 提浮子，向上运行，液体
A11: [17:47:09.672]收← | B11: 01 03 20 03 25 00 00 C1 FE 00 00 11 22 00 00 00 00 08 60 48 8E 50 A0 00 00 F9 CD 00 00 5B 98 00 00 00 00 5C 07 | C11: =HEX2DEC(MID(B11,10,2)&MID(B11,13,2)) -> 805 | D11: =HEX2DEC(MID($B11,10+6*D$1,2)&MID($B11,13+6*D$1,2)) -> 0 | E11: =(HEX2DEC(MID($B11,10+6*E$1,2)&MID($B11,13+6*E$1,2))-65536)/100 -> -158.74 | F11: =HEX2DEC(MID($B11,10+6*F$1,2)&MID($B11,13+6*F$1,2)) -> 0 | G11: =HEX2DEC(MID($B11,10+6*G$1,2)&MID($B11,13+6*G$1,2))/10 -> 438.6 | H11: =HEX2DEC(MID($B11,10+6*H$1,2)&MID($B11,13+6*H$1,2)) -> 0 | I11: =HEX2DEC(MID($B11,10+6*I$1,2)&MID($B11,13+6*I$1,2)) -> 0 | J11: =HEX2DEC(MID($B11,10+6*J$1,2)&MID($B11,13+6*J$1,2)) -> 2144 | K11: =HEX2DEC(MID($B11,10+6*K$1,2)&MID($B11,13+6*K$1,2)) -> 18574 | L11: =HEX2DEC(MID($B11,10+6*L$1,2)&MID($B11,13+6*L$1,2))/10 -> 2064 | M11: =HEX2DEC(MID($B11,10+6*M$1,2)&MID($B11,13+6*M$1,2)) -> 0 | N11: =(HEX2DEC(MID($B11,10+6*N$1,2)&MID($B11,13+6*N$1,2))-65536)/10 -> -158.7 | O11: =HEX2DEC(MID($B11,10+6*O$1,2)&MID($B11,13+6*O$1,2)) -> 0 | P11: =HEX2DEC(MID($B11,10+6*P$1,2)&MID($B11,13+6*P$1,2)) -> 23448 | Q11: =HEX2DEC(MID($B11,10+6*Q$1,2)&MID($B11,13+6*Q$1,2)) -> 0 | R11: =HEX2DEC(MID($B11,10+6*R$1,2)&MID($B11,13+6*R$1,2)) -> 0 | S11: =VLOOKUP(J11,设备状态表!$D$3:$E$14,2,0) -> 提浮子，向上运行，液体
A12: [17:47:20.908]收← | B12: 01 03 20 04 99 00 00 C1 FE 00 00 11 21 00 00 00 00 08 60 48 8E 50 C0 00 00 F9 CD 00 00 5B 98 00 00 00 00 4A 53 | C12: =HEX2DEC(MID(B12,10,2)&MID(B12,13,2)) -> 1177 | D12: =HEX2DEC(MID($B12,10+6*D$1,2)&MID($B12,13+6*D$1,2)) -> 0 | E12: =(HEX2DEC(MID($B12,10+6*E$1,2)&MID($B12,13+6*E$1,2))-65536)/100 -> -158.74 | F12: =HEX2DEC(MID($B12,10+6*F$1,2)&MID($B12,13+6*F$1,2)) -> 0 | G12: =HEX2DEC(MID($B12,10+6*G$1,2)&MID($B12,13+6*G$1,2))/10 -> 438.5 | H12: =HEX2DEC(MID($B12,10+6*H$1,2)&MID($B12,13+6*H$1,2)) -> 0 | I12: =HEX2DEC(MID($B12,10+6*I$1,2)&MID($B12,13+6*I$1,2)) -> 0 | J12: =HEX2DEC(MID($B12,10+6*J$1,2)&MID($B12,13+6*J$1,2)) -> 2144 | K12: =HEX2DEC(MID($B12,10+6*K$1,2)&MID($B12,13+6*K$1,2)) -> 18574 | L12: =HEX2DEC(MID($B12,10+6*L$1,2)&MID($B12,13+6*L$1,2))/10 -> 2067.2 | M12: =HEX2DEC(MID($B12,10+6*M$1,2)&MID($B12,13+6*M$1,2)) -> 0 | N12: =(HEX2DEC(MID($B12,10+6*N$1,2)&MID($B12,13+6*N$1,2))-65536)/10 -> -158.7 | O12: =HEX2DEC(MID($B12,10+6*O$1,2)&MID($B12,13+6*O$1,2)) -> 0 | P12: =HEX2DEC(MID($B12,10+6*P$1,2)&MID($B12,13+6*P$1,2)) -> 23448 | Q12: =HEX2DEC(MID($B12,10+6*Q$1,2)&MID($B12,13+6*Q$1,2)) -> 0 | R12: =HEX2DEC(MID($B12,10+6*R$1,2)&MID($B12,13+6*R$1,2)) -> 0 | S12: =VLOOKUP(J12,设备状态表!$D$3:$E$14,2,0) -> 提浮子，向上运行，液体
A13: [17:47:22.519]收← | B13: 01 03 20 04 CF 00 00 C1 FD 00 00 11 22 00 00 00 00 08 60 48 8E 50 60 00 00 F9 CD 00 00 5B 98 00 00 00 00 FF FE | C13: =HEX2DEC(MID(B13,10,2)&MID(B13,13,2)) -> 1231 | D13: =HEX2DEC(MID($B13,10+6*D$1,2)&MID($B13,13+6*D$1,2)) -> 0 | E13: =(HEX2DEC(MID($B13,10+6*E$1,2)&MID($B13,13+6*E$1,2))-65536)/100 -> -158.75 | F13: =HEX2DEC(MID($B13,10+6*F$1,2)&MID($B13,13+6*F$1,2)) -> 0 | G13: =HEX2DEC(MID($B13,10+6*G$1,2)&MID($B13,13+6*G$1,2))/10 -> 438.6 | H13: =HEX2DEC(MID($B13,10+6*H$1,2)&MID($B13,13+6*H$1,2)) -> 0 | I13: =HEX2DEC(MID($B13,10+6*I$1,2)&MID($B13,13+6*I$1,2)) -> 0 | J13: =HEX2DEC(MID($B13,10+6*J$1,2)&MID($B13,13+6*J$1,2)) -> 2144 | K13: =HEX2DEC(MID($B13,10+6*K$1,2)&MID($B13,13+6*K$1,2)) -> 18574 | L13: =HEX2DEC(MID($B13,10+6*L$1,2)&MID($B13,13+6*L$1,2))/10 -> 2057.6 | M13: =HEX2DEC(MID($B13,10+6*M$1,2)&MID($B13,13+6*M$1,2)) -> 0 | N13: =(HEX2DEC(MID($B13,10+6*N$1,2)&MID($B13,13+6*N$1,2))-65536)/10 -> -158.7 | O13: =HEX2DEC(MID($B13,10+6*O$1,2)&MID($B13,13+6*O$1,2)) -> 0 | P13: =HEX2DEC(MID($B13,10+6*P$1,2)&MID($B13,13+6*P$1,2)) -> 23448 | Q13: =HEX2DEC(MID($B13,10+6*Q$1,2)&MID($B13,13+6*Q$1,2)) -> 0 | R13: =HEX2DEC(MID($B13,10+6*R$1,2)&MID($B13,13+6*R$1,2)) -> 0 | S13: =VLOOKUP(J13,设备状态表!$D$3:$E$14,2,0) -> 提浮子，向上运行，液体
